Workbook
Name \A: #REF!
Name \A: #REF!
Name \A: #REF!
Name \A: #REF!
Name \B: #REF!
Name \B: #REF!
Name \B: #REF!
Name \C: #REF!
Name \C: #REF!
Name \C: #REF!
Name \D: #REF!
Name \D: #REF!
Name \D: #REF!
Name \D: #REF!
Name \E: #REF!
Name \E: #REF!
Name \E: #REF!
Name \E: #REF!
Name \F: #REF!
Name \F: #REF!
Name \F: #REF!
Name \F: #REF!
Name \G: #REF!
Name \G: #REF!
Name \G: #REF!
Name \G: #REF!
Name \H: #REF!
Name \H: #REF!
Name \H: #REF!
Name \H: #REF!
Name \I: #REF!
Name \I: #REF!
Name \I: #REF!
Name \I: #REF!
Name \J: #REF!
Name \J: #REF!
Name \J: #REF!
Name \J: #REF!
Name \K: #REF!
Name \K: #REF!
Name \K: #REF!
Name \K: #REF!
Name \L: #REF!
Name \L: #REF!
Name \L: #REF!
Name \L: #REF!
Name \LX1: #REF!
Name \LX1: #REF!
Name \LX1: #REF!
Name \LX1: #REF!
Name \M: #REF!
Name \M: #REF!
Name \M: #REF!
Name \M: #REF!
Name \P: #REF!
Name \P: #REF!
Name \P: #REF!
Name \P: #REF!
Name \Q: #REF!
Name \Q: #REF!

Sheet REKAP MATERIAL
C1: PT. PLN ( PERSERO )
C2: =RAB!C2 -> UNIT INDUK DISTRIBUSI JAWA TENGAH & DI YOGYAKARTA
B4: REKAP KEBUTUHAN MATERIAL
B7: NO | C7: URAIAN | D7: GOL | E7: SAT | F7: VOL TOTAL | G7: HARGA SATUAN | H7: LOKASI | I7: NO PRK | J7: NAMA PROGRAM | K7: INISIATIF STRATEGIS
B11: + | C11: REKAP MATERIAL
A12: 1 | B12: =IF(C12="","",A12) -> 1 | C12: =IF(ISERROR(OFFSET($C$713,MATCH(A12,$F$714:$F$1320,0),0)),"",OFFSET($C$713,MATCH(A12,$F$714:$F$1320,0),0)) -> KWH Elektronik; 3P; 4W; 220/380V; 5(80) A; kls 1 (Pengukuran Langsung) | D12: =IF(ISERROR(OFFSET('HARGA SATUAN'!$D$6,MATCH(C12,'HARGA SATUAN'!$C$7:$C$1492,0),0)),"",OFFSET('HARGA SATUAN'!$D$6,MATCH(C12,'HARGA SATUAN'!$C$7:$C$1492,0),0)) -> MDU-KD | E12: =IF(B12="+","Unit",IF(ISERROR(OFFSET('HARGA SATUAN'!$E$6,MATCH(C12,'HARGA SATUAN'!$C$7:$C$1492,0),0)),"",OFFSET('HARGA SATUAN'!$E$6,MATCH(C12,'HARGA SATUAN'!$C$7:$C$1492,0),0))) -> Bh | F12: =IF(ISERROR(OFFSET($D$713,MATCH(A12,$F$714:$F$1320,0),0)),"",OFFSET($D$713,MATCH(A12,$F$714:$F$1320,0),0)) -> 1 | G12: =IF(ISERROR(OFFSET('HARGA SATUAN'!$I$6,MATCH(C12,'HARGA SATUAN'!$C$7:$C$1492,0),0)),"",OFFSET('HARGA SATUAN'!$I$6,MATCH(C12,'HARGA SATUAN'!$C$7:$C$1492,0),0)) -> 1427400 | H12: =IF(B12="","",#REF!) -> #REF! | I12: =IF(B12="","",#REF!) -> #REF! | J12: =IF(B12="","",#REF!) -> #REF! | K12: =IF(B12="","",#REF!) -> #REF! | L12: =IF(C12="","",#REF!) -> #REF!
A13: 2 | B13: =IF(C13="","",A13) -> 2 | C13: =IF(ISERROR(OFFSET($C$713,MATCH(A13,$F$714:$F$1320,0),0)),"",OFFSET($C$713,MATCH(A13,$F$714:$F$1320,0),0)) -> Smart Box Langsung Daya 13.2 kVA MCCB 20 A | D13: =IF(ISERROR(OFFSET('HARGA SATUAN'!$D$6,MATCH(C13,'HARGA SATUAN'!$C$7:$C$1492,0),0)),"",OFFSET('HARGA SATUAN'!$D$6,MATCH(C13,'HARGA SATUAN'!$C$7:$C$1492,0),0)) -> MDU-KD | E13: =IF(B13="+","Unit",IF(ISERROR(OFFSET('HARGA SATUAN'!$E$6,MATCH(C13,'HARGA SATUAN'!$C$7:$C$1492,0),0)),"",OFFSET('HARGA SATUAN'!$E$6,MATCH(C13,'HARGA SATUAN'!$C$7:$C$1492,0),0))) -> Unit | F13: =IF(ISERROR(OFFSET($D$713,MATCH(A13,$F$714:$F$1320,0),0)),"",OFFSET($D$713,MATCH(A13,$F$714:$F$1320,0),0)) -> 1 | G13: =IF(ISERROR(OFFSET('HARGA SATUAN'!$I$6,MATCH(C13,'HARGA SATUAN'!$C$7:$C$1492,0),0)),"",OFFSET('HARGA SATUAN'!$I$6,MATCH(C13,'HARGA SATUAN'!$C$7:$C$1492,0),0)) -> 3564900 | H13: =IF(B13="","",#REF!) -> #REF! | I13: =IF(B13="","",#REF!) -> #REF! | J13: =IF(B13="","",#REF!) -> #REF! | K13: =IF(B13="","",#REF!) -> #REF! | L13: =IF(C13="","",#REF!) -> #REF!
A14: 3 | B14: =IF(C14="","",A14) -> 3 | C14: =IF(ISERROR(OFFSET($C$713,MATCH(A14,$F$714:$F$1320,0),0)),"",OFFSET($C$713,MATCH(A14,$F$714:$F$1320,0),0)) -> NFA2X-T 3x70+1x70 | D14: =IF(ISERROR(OFFSET('HARGA SATUAN'!$D$6,MATCH(C14,'HARGA SATUAN'!$C$7:$C$1492,0),0)),"",OFFSET('HARGA SATUAN'!$D$6,MATCH(C14,'HARGA SATUAN'!$C$7:$C$1492,0),0)) -> MDU-KD | E14: =IF(B14="+","Unit",IF(ISERROR(OFFSET('HARGA SATUAN'!$E$6,MATCH(C14,'HARGA SATUAN'!$C$7:$C$1492,0),0)),"",OFFSET('HARGA SATUAN'!$E$6,MATCH(C14,'HARGA SATUAN'!$C$7:$C$1492,0),0))) -> Mtr | F14: =IF(ISERROR(OFFSET($D$713,MATCH(A14,$F$714:$F$1320,0),0)),"",OFFSET($D$713,MATCH(A14,$F$714:$F$1320,0),0)) -> 130 | G14: =IF(ISERROR(OFFSET('HARGA SATUAN'!$I$6,MATCH(C14,'HARGA SATUAN'!$C$7:$C$1492,0),0)),"",OFFSET('HARGA SATUAN'!$I$6,MATCH(C14,'HARGA SATUAN'!$C$7:$C$1492,0),0)) -> 54500 | H14: =IF(B14="","",#REF!) -> #REF! | I14: =IF(B14="","",#REF!) -> #REF! | J14: =IF(B14="","",#REF!) -> #REF! | K14: =IF(B14="","",#REF!) -> #REF! | L14: =IF(C14="","",#REF!) -> #REF!
A15: 4 | B15: =IF(C15="","",A15) -> 4 | C15: =IF(ISERROR(OFFSET($C$713,MATCH(A15,$F$714:$F$1320,0),0)),"",OFFSET($C$713,MATCH(A15,$F$714:$F$1320,0),0)) -> NFA2X 4 x 16 mm² | D15: =IF(ISERROR(OFFSET('HARGA SATUAN'!$D$6,MATCH(C15,'HARGA SATUAN'!$C$7:$C$1492,0),0)),"",OFFSET('HARGA SATUAN'!$D$6,MATCH(C15,'HARGA SATUAN'!$C$7:$C$1492,0),0)) -> MDU-KD | E15: =IF(B15="+","Unit",IF(ISERROR(OFFSET('HARGA SATUAN'!$E$6,MATCH(C15,'HARGA SATUAN'!$C$7:$C$1492,0),0)),"",OFFSET('HARGA SATUAN'!$E$6,MATCH(C15,'HARGA SATUAN'!$C$7:$C$1492,0),0))) -> Mtr | F15: =IF(ISERROR(OFFSET($D$713,MATCH(A15,$F$714:$F$1320,0),0)),"",OFFSET($D$713,MATCH(A15,$F$714:$F$1320,0),0)) -> 50 | G15: =IF(ISERROR(OFFSET('HARGA SATUAN'!$I$6,MATCH(C15,'HARGA SATUAN'!$C$7:$C$1492,0),0)),"",OFFSET('HARGA SATUAN'!$I$6,MATCH(C15,'HARGA SATUAN'!$C$7:$C$1492,0),0)) -> 13500 | H15: =IF(B15="","",#REF!) -> #REF! | I15: =IF(B15="","",#REF!) -> #REF! | J15: =IF(B15="","",#REF!) -> #REF! | K15: =IF(B15="","",#REF!) -> #REF! | L15: =IF(C15="","",#REF!) -> #REF!
A16: 5 | B16: =IF(C16="","",A16) | C16: =IF(ISERROR(OFFSET($C$713,MATCH(A16,$F$714:$F$1320,0),0)),"",OFFSET($C$713,MATCH(A16,$F$714:$F$1320,0),0)) | D16: =IF(ISERROR(OFFSET('HARGA SATUAN'!$D$6,MATCH(C16,'HARGA SATUAN'!$C$7:$C$1492,0),0)),"",OFFSET('HARGA SATUAN'!$D$6,MATCH(C16,'HARGA SATUAN'!$C$7:$C$1492,0),0)) | E16: =IF(B16="+","Unit",IF(ISERROR(OFFSET('HARGA SATUAN'!$E$6,MATCH(C16,'HARGA SATUAN'!$C$7:$C$1492,0),0)),"",OFFSET('HARGA SATUAN'!$E$6,MATCH(C16,'HARGA SATUAN'!$C$7:$C$1492,0),0))) -> 0 | F16: =IF(ISERROR(OFFSET($D$713,MATCH(A16,$F$714:$F$1320,0),0)),"",OFFSET($D$713,MATCH(A16,$F$714:$F$1320,0),0)) | G16: =IF(ISERROR(OFFSET('HARGA SATUAN'!$I$6,MATCH(C16,'HARGA SATUAN'!$C$7:$C$1492,0),0)),"",OFFSET('HARGA SATUAN'!$I$6,MATCH(C16,'HARGA SATUAN'!$C$7:$C$1492,0),0)) -> 0 | H16: =IF(B16="","",#REF!) | I16: =IF(B16="","",#REF!) | J16: =IF(B16="","",#REF!) | K16: =IF(B16="","",#REF!) | L16: =IF(C16="","",#REF!)
A17: 6 | B17: =IF(C17="","",A17) | C17: =IF(ISERROR(OFFSET($C$713,MATCH(A17,$F$714:$F$1320,0),0)),"",OFFSET($C$713,MATCH(A17,$F$714:$F$1320,0),0)) | D17: =IF(ISERROR(OFFSET('HARGA SATUAN'!$D$6,MATCH(C17,'HARGA SATUAN'!$C$7:$C$1492,0),0)),"",OFFSET('HARGA SATUAN'!$D$6,MATCH(C17,'HARGA SATUAN'!$C$7:$C$1492,0),0)) | E17: =IF(B17="+","Unit",IF(ISERROR(OFFSET('HARGA SATUAN'!$E$6,MATCH(C17,'HARGA SATUAN'!$C$7:$C$1492,0),0)),"",OFFSET('HARGA SATUAN'!$E$6,MATCH(C17,'HARGA SATUAN'!$C$7:$C$1492,0),0))) -> 0 | F17: =IF(ISERROR(OFFSET($D$713,MATCH(A17,$F$714:$F$1320,0),0)),"",OFFSET($D$713,MATCH(A17,$F$714:$F$1320,0),0)) | G17: =IF(ISERROR(OFFSET('HARGA SATUAN'!$I$6,MATCH(C17,'HARGA SATUAN'!$C$7:$C$1492,0),0)),"",OFFSET('HARGA SATUAN'!$I$6,MATCH(C17,'HARGA SATUAN'!$C$7:$C$1492,0),0)) -> 0 | H17: =IF(B17="","",#REF!) | I17: =IF(B17="","",#REF!) | J17: =IF(B17="","",#REF!) | K17: =IF(B17="","",#REF!) | L17: =IF(C17="","",#REF!)
A18: 7 | B18: =IF(C18="","",A18) | C18: =IF(ISERROR(OFFSET($C$713,MATCH(A18,$F$714:$F$1320,0),0)),"",OFFSET($C$713,MATCH(A18,$F$714:$F$1320,0),0)) | D18: =IF(ISERROR(OFFSET('HARGA SATUAN'!$D$6,MATCH(C18,'HARGA SATUAN'!$C$7:$C$1492,0),0)),"",OFFSET('HARGA SATUAN'!$D$6,MATCH(C18,'HARGA SATUAN'!$C$7:$C$1492,0),0)) | E18: =IF(B18="+","Unit",IF(ISERROR(OFFSET('HARGA SATUAN'!$E$6,MATCH(C18,'HARGA SATUAN'!$C$7:$C$1492,0),0)),"",OFFSET('HARGA SATUAN'!$E$6,MATCH(C18,'HARGA SATUAN'!$C$7:$C$1492,0),0))) -> 0 | F18: =IF(ISERROR(OFFSET($D$713,MATCH(A18,$F$714:$F$1320,0),0)),"",OFFSET($D$713,MATCH(A18,$F$714:$F$1320,0),0)) | G18: =IF(ISERROR(OFFSET('HARGA SATUAN'!$I$6,MATCH(C18,'HARGA SATUAN'!$C$7:$C$1492,0),0)),"",OFFSET('HARGA SATUAN'!$I$6,MATCH(C18,'HARGA SATUAN'!$C$7:$C$1492,0),0)) -> 0 | H18: =IF(B18="","",#REF!) | I18: =IF(B18="","",#REF!) | J18: =IF(B18="","",#REF!) | K18: =IF(B18="","",#REF!) | L18: =IF(C18="","",#REF!)
A19: 8 | B19: =IF(C19="","",A19) | C19: =IF(ISERROR(OFFSET($C$713,MATCH(A19,$F$714:$F$1320,0),0)),"",OFFSET($C$713,MATCH(A19,$F$714:$F$1320,0),0)) | D19: =IF(ISERROR(OFFSET('HARGA SATUAN'!$D$6,MATCH(C19,'HARGA SATUAN'!$C$7:$C$1492,0),0)),"",OFFSET('HARGA SATUAN'!$D$6,MATCH(C19,'HARGA SATUAN'!$C$7:$C$1492,0),0)) | E19: =IF(B19="+","Unit",IF(ISERROR(OFFSET('HARGA SATUAN'!$E$6,MATCH(C19,'HARGA SATUAN'!$C$7:$C$1492,0),0)),"",OFFSET('HARGA SATUAN'!$E$6,MATCH(C19,'HARGA SATUAN'!$C$7:$C$1492,0),0))) -> 0 | F19: =IF(ISERROR(OFFSET($D$713,MATCH(A19,$F$714:$F$1320,0),0)),"",OFFSET($D$713,MATCH(A19,$F$714:$F$1320,0),0)) | G19: =IF(ISERROR(OFFSET('HARGA SATUAN'!$I$6,MATCH(C19,'HARGA SATUAN'!$C$7:$C$1492,0),0)),"",OFFSET('HARGA SATUAN'!$I$6,MATCH(C19,'HARGA SATUAN'!$C$7:$C$1492,0),0)) -> 0 | H19: =IF(B19="","",#REF!) | I19: =IF(B19="","",#REF!) | J19: =IF(B19="","",#REF!) | K19: =IF(B19="","",#REF!) | L19: =IF(C19="","",#REF!)
A20: 9 | B20: =IF(C20="","",A20) | C20: =IF(ISERROR(OFFSET($C$713,MATCH(A20,$F$714:$F$1320,0),0)),"",OFFSET($C$713,MATCH(A20,$F$714:$F$1320,0),0)) | D20: =IF(ISERROR(OFFSET('HARGA SATUAN'!$D$6,MATCH(C20,'HARGA SATUAN'!$C$7:$C$1492,0),0)),"",OFFSET('HARGA SATUAN'!$D$6,MATCH(C20,'HARGA SATUAN'!$C$7:$C$1492,0),0)) | E20: =IF(B20="+","Unit",IF(ISERROR(OFFSET('HARGA SATUAN'!$E$6,MATCH(C20,'HARGA SATUAN'!$C$7:$C$1492,0),0)),"",OFFSET('HARGA SATUAN'!$E$6,MATCH(C20,'HARGA SATUAN'!$C$7:$C$1492,0),0))) -> 0 | F20: =IF(ISERROR(OFFSET($D$713,MATCH(A20,$F$714:$F$1320,0),0)),"",OFFSET($D$713,MATCH(A20,$F$714:$F$1320,0),0)) | G20: =IF(ISERROR(OFFSET('HARGA SATUAN'!$I$6,MATCH(C20,'HARGA SATUAN'!$C$7:$C$1492,0),0)),"",OFFSET('HARGA SATUAN'!$I$6,MATCH(C20,'HARGA SATUAN'!$C$7:$C$1492,0),0)) -> 0 | H20: =IF(B20="","",#REF!) | I20: =IF(B20="","",#REF!) | J20: =IF(B20="","",#REF!) | K20: =IF(B20="","",#REF!) | L20: =IF(C20="","",#REF!)
A21: 10 | B21: =IF(C21="","",A21) | C21: =IF(ISERROR(OFFSET($C$713,MATCH(A21,$F$714:$F$1320,0),0)),"",OFFSET($C$713,MATCH(A21,$F$714:$F$1320,0),0)) | D21: =IF(ISERROR(OFFSET('HARGA SATUAN'!$D$6,MATCH(C21,'HARGA SATUAN'!$C$7:$C$1492,0),0)),"",OFFSET('HARGA SATUAN'!$D$6,MATCH(C21,'HARGA SATUAN'!$C$7:$C$1492,0),0)) | E21: =IF(B21="+","Unit",IF(ISERROR(OFFSET('HARGA SATUAN'!$E$6,MATCH(C21,'HARGA SATUAN'!$C$7:$C$1492,0),0)),"",OFFSET('HARGA SATUAN'!$E$6,MATCH(C21,'HARGA SATUAN'!$C$7:$C$1492,0),0))) -> 0 | F21: =IF(ISERROR(OFFSET($D$713,MATCH(A21,$F$714:$F$1320,0),0)),"",OFFSET($D$713,MATCH(A21,$F$714:$F$1320,0),0)) | G21: =IF(ISERROR(OFFSET('HARGA SATUAN'!$I$6,MATCH(C21,'HARGA SATUAN'!$C$7:$C$1492,0),0)),"",OFFSET('HARGA SATUAN'!$I$6,MATCH(C21,'HARGA SATUAN'!$C$7:$C$1492,0),0)) -> 0 | H21: =IF(B21="","",#REF!) | I21: =IF(B21="","",#REF!) | J21: =IF(B21="","",#REF!) | K21: =IF(B21="","",#REF!) | L21: =IF(C21="","",#REF!)
A22: 11 | B22: =IF(C22="","",A22) | C22: =IF(ISERROR(OFFSET($C$713,MATCH(A22,$F$714:$F$1320,0),0)),"",OFFSET($C$713,MATCH(A22,$F$714:$F$1320,0),0)) | D22: =IF(ISERROR(OFFSET('HARGA SATUAN'!$D$6,MATCH(C22,'HARGA SATUAN'!$C$7:$C$1492,0),0)),"",OFFSET('HARGA SATUAN'!$D$6,MATCH(C22,'HARGA SATUAN'!$C$7:$C$1492,0),0)) | E22: =IF(B22="+","Unit",IF(ISERROR(OFFSET('HARGA SATUAN'!$E$6,MATCH(C22,'HARGA SATUAN'!$C$7:$C$1492,0),0)),"",OFFSET('HARGA SATUAN'!$E$6,MATCH(C22,'HARGA SATUAN'!$C$7:$C$1492,0),0))) -> 0 | F22: =IF(ISERROR(OFFSET($D$713,MATCH(A22,$F$714:$F$1320,0),0)),"",OFFSET($D$713,MATCH(A22,$F$714:$F$1320,0),0)) | G22: =IF(ISERROR(OFFSET('HARGA SATUAN'!$I$6,MATCH(C22,'HARGA SATUAN'!$C$7:$C$1492,0),0)),"",OFFSET('HARGA SATUAN'!$I$6,MATCH(C22,'HARGA SATUAN'!$C$7:$C$1492,0),0)) -> 0 | H22: =IF(B22="","",#REF!) | I22: =IF(B22="","",#REF!) | J22: =IF(B22="","",#REF!) | K22: =IF(B22="","",#REF!) | L22: =IF(C22="","",#REF!)
A23: 12 | B23: =IF(C23="","",A23) | C23: =IF(ISERROR(OFFSET($C$713,MATCH(A23,$F$714:$F$1320,0),0)),"",OFFSET($C$713,MATCH(A23,$F$714:$F$1320,0),0)) | D23: =IF(ISERROR(OFFSET('HARGA SATUAN'!$D$6,MATCH(C23,'HARGA SATUAN'!$C$7:$C$1492,0),0)),"",OFFSET('HARGA SATUAN'!$D$6,MATCH(C23,'HARGA SATUAN'!$C$7:$C$1492,0),0)) | E23: =IF(B23="+","Unit",IF(ISERROR(OFFSET('HARGA SATUAN'!$E$6,MATCH(C23,'HARGA SATUAN'!$C$7:$C$1492,0),0)),"",OFFSET('HARGA SATUAN'!$E$6,MATCH(C23,'HARGA SATUAN'!$C$7:$C$1492,0),0))) -> 0 | F23: =IF(ISERROR(OFFSET($D$713,MATCH(A23,$F$714:$F$1320,0),0)),"",OFFSET($D$713,MATCH(A23,$F$714:$F$1320,0),0)) | G23: =IF(ISERROR(OFFSET('HARGA SATUAN'!$I$6,MATCH(C23,'HARGA SATUAN'!$C$7:$C$1492,0),0)),"",OFFSET('HARGA SATUAN'!$I$6,MATCH(C23,'HARGA SATUAN'!$C$7:$C$1492,0),0)) -> 0 | H23: =IF(B23="","",#REF!) | I23: =IF(B23="","",#REF!) | J23: =IF(B23="","",#REF!) | K23: =IF(B23="","",#REF!) | L23: =IF(C23="","",#REF!)
... A710: 699 | B710: =IF(C710="","",A710) | C710: =IF(ISERROR(OFFSET($C$713,MATCH(A710,$F$714:$F$1320,0),0)),"",OFFSET($C$713,MATCH(A710,$F$714:$F$1320,0),0)) | D710: =IF(ISERROR(OFFSET('HARGA SATUAN'!$D$6,MATCH(C710,'HARGA SATUAN'!$C$7:$C$1492,0),0)),"",OFFSET('HARGA SATUAN'!$D$6,MATCH(C710,'HARGA SATUAN'!$C$7:$C$1492,0),0)) | E710: =IF(B710="+","Unit",IF(ISERROR(OFFSET('HARGA SATUAN'!$E$6,MATCH(C710,'HARGA SATUAN'!$C$7:$C$1492,0),0)),"",OFFSET('HARGA SATUAN'!$E$6,MATCH(C710,'HARGA SATUAN'!$C$7:$C$1492,0),0))) -> 0 | F710: =IF(ISERROR(OFFSET($D$713,MATCH(A710,$F$714:$F$1320,0),0)),"",OFFSET($D$713,MATCH(A710,$F$714:$F$1320,0),0)) | G710: =IF(ISERROR(OFFSET('HARGA SATUAN'!$I$6,MATCH(C710,'HARGA SATUAN'!$C$7:$C$1492,0),0)),"",OFFSET('HARGA SATUAN'!$I$6,MATCH(C710,'HARGA SATUAN'!$C$7:$C$1492,0),0)) -> 0 | H710: =IF(B710="","",#REF!) | I710: =IF(B710="","",#REF!) | J710: =IF(B710="","",#REF!) | K710: =IF(B710="","",#REF!) | L710: =IF(C710="","",#REF!)
A711: 700 | B711: =IF(C711="","",A711) | C711: =IF(ISERROR(OFFSET($C$713,MATCH(A711,$F$714:$F$1320,0),0)),"",OFFSET($C$713,MATCH(A711,$F$714:$F$1320,0),0)) | F711: =IF(ISERROR(OFFSET($D$713,MATCH(A711,$F$714:$F$1320,0),0)),"",OFFSET($D$713,MATCH(A711,$F$714:$F$1320,0),0)) | G711: =IF(ISERROR(OFFSET('HARGA SATUAN'!$I$6,MATCH(C711,'HARGA SATUAN'!$C$7:$C$1492,0),0)),"",OFFSET('HARGA SATUAN'!$I$6,MATCH(C711,'HARGA SATUAN'!$C$7:$C$1492,0),0)) -> 0 | H711: =IF(B711="","",#REF!) | I711: =IF(B711="","",#REF!) | J711: =IF(B711="","",#REF!) | K711: =IF(B711="","",#REF!) | L711: =IF(C711="","",#REF!)
B714: 1 | C714: =IF(ISERROR(OFFSET('HARGA SATUAN'!$C$6,MATCH(B714,'HARGA SATUAN'!$N$7:$N$1492,0),0)),"",OFFSET('HARGA SATUAN'!$C$6,MATCH(B714,'HARGA SATUAN'!$N$7:$N$1492,0),0)) -> KWH MPB; 1P;230V;5(60)A;1;2W | D714: =SUMIFS(RAB!$F$14:$F$80,RAB!$C$14:$C$80,C714) -> 0 | E714: =IF(D714=0,0,1) -> 0 | F714: =IF(D714=0,0,SUM($E$713:E714)) -> 0
B715: 2 | C715: =IF(ISERROR(OFFSET('HARGA SATUAN'!$C$6,MATCH(B715,'HARGA SATUAN'!$N$7:$N$1492,0),0)),"",OFFSET('HARGA SATUAN'!$C$6,MATCH(B715,'HARGA SATUAN'!$N$7:$N$1492,0),0)) -> KWH Elektronik; 1P; 2W; 230 V; 5(40) A; kls 1 (combo); register drum | D715: =SUMIFS(RAB!$F$14:$F$80,RAB!$C$14:$C$80,C715) -> 0 | E715: =IF(D715=0,0,1) -> 0 | F715: =IF(D715=0,0,SUM($E$713:E715)) -> 0
B716: 3 | C716: =IF(ISERROR(OFFSET('HARGA SATUAN'!$C$6,MATCH(B716,'HARGA SATUAN'!$N$7:$N$1492,0),0)),"",OFFSET('HARGA SATUAN'!$C$6,MATCH(B716,'HARGA SATUAN'!$N$7:$N$1492,0),0)) -> KWH Elektronik; 1P; 2W; 230 V; 5(100) A; kls 1 termasuk modem 3G/4G | D716: =SUMIFS(RAB!$F$14:$F$80,RAB!$C$14:$C$80,C716) -> 0 | E716: =IF(D716=0,0,1) -> 0 | F716: =IF(D716=0,0,SUM($E$713:E716)) -> 0
B717: 4 | C717: =IF(ISERROR(OFFSET('HARGA SATUAN'!$C$6,MATCH(B717,'HARGA SATUAN'!$N$7:$N$1492,0),0)),"",OFFSET('HARGA SATUAN'!$C$6,MATCH(B717,'HARGA SATUAN'!$N$7:$N$1492,0),0)) -> KWH Elektronik; 3P; 4W; 57.7-100V/220-400V; 5 A; kls 0.2 (meter pembanding) | D717: =SUMIFS(RAB!$F$14:$F$80,RAB!$C$14:$C$80,C717) -> 0 | E717: =IF(D717=0,0,1) -> 0 | F717: =IF(D717=0,0,SUM($E$713:E717)) -> 0
B718: 5 | C718: =IF(ISERROR(OFFSET('HARGA SATUAN'!$C$6,MATCH(B718,'HARGA SATUAN'!$N$7:$N$1492,0),0)),"",OFFSET('HARGA SATUAN'!$C$6,MATCH(B718,'HARGA SATUAN'!$N$7:$N$1492,0),0)) -> KWH Elektronik; 3P; 4W; 220/380V; 5(80) A; kls 1 (Pengukuran Langsung) | D718: =SUMIFS(RAB!$F$14:$F$80,RAB!$C$14:$C$80,C718) -> 1 | E718: =IF(D718=0,0,1) -> 1 | F718: =IF(D718=0,0,SUM($E$713:E718)) -> 1
B719: 6 | C719: =IF(ISERROR(OFFSET('HARGA SATUAN'!$C$6,MATCH(B719,'HARGA SATUAN'!$N$7:$N$1492,0),0)),"",OFFSET('HARGA SATUAN'!$C$6,MATCH(B719,'HARGA SATUAN'!$N$7:$N$1492,0),0)) -> KWH Elektronik; 3P; 4W; 57.7-100V/220-400V; 5(10) A; kls 0.5 (Pengukuran Tidak Langsung) | D719: =SUMIFS(RAB!$F$14:$F$80,RAB!$C$14:$C$80,C719) -> 0 | E719: =IF(D719=0,0,1) -> 0 | F719: =IF(D719=0,0,SUM($E$713:E719)) -> 0
B720: 7 | C720: =IF(ISERROR(OFFSET('HARGA SATUAN'!$C$6,MATCH(B720,'HARGA SATUAN'!$N$7:$N$1492,0),0)),"",OFFSET('HARGA SATUAN'!$C$6,MATCH(B720,'HARGA SATUAN'!$N$7:$N$1492,0),0)) -> KWH Elektronik; 3P; 4W; 220/380V; 5(10); kls 1 (Pengukuran Tidak Langsung) | D720: =SUMIFS(RAB!$F$14:$F$80,RAB!$C$14:$C$80,C720) -> 0 | E720: =IF(D720=0,0,1) -> 0 | F720: =IF(D720=0,0,SUM($E$713:E720)) -> 0
B721: 8 | C721: =IF(ISERROR(OFFSET('HARGA SATUAN'!$C$6,MATCH(B721,'HARGA SATUAN'!$N$7:$N$1492,0),0)),"",OFFSET('HARGA SATUAN'!$C$6,MATCH(B721,'HARGA SATUAN'!$N$7:$N$1492,0),0)) -> MCB 1 Fasa 2 A | D721: =SUMIFS(RAB!$F$14:$F$80,RAB!$C$14:$C$80,C721) -> 0 | E721: =IF(D721=0,0,1) -> 0 | F721: =IF(D721=0,0,SUM($E$713:E721)) -> 0
B722: 9 | C722: =IF(ISERROR(OFFSET('HARGA SATUAN'!$C$6,MATCH(B722,'HARGA SATUAN'!$N$7:$N$1492,0),0)),"",OFFSET('HARGA SATUAN'!$C$6,MATCH(B722,'HARGA SATUAN'!$N$7:$N$1492,0),0)) -> MCB 1 Fasa 4 A | D722: =SUMIFS(RAB!$F$14:$F$80,RAB!$C$14:$C$80,C722) -> 0 | E722: =IF(D722=0,0,1) -> 0 | F722: =IF(D722=0,0,SUM($E$713:E722)) -> 0
B723: 10 | C723: =IF(ISERROR(OFFSET('HARGA SATUAN'!$C$6,MATCH(B723,'HARGA SATUAN'!$N$7:$N$1492,0),0)),"",OFFSET('HARGA SATUAN'!$C$6,MATCH(B723,'HARGA SATUAN'!$N$7:$N$1492,0),0)) -> MCB 1 Fasa 6 A | D723: =SUMIFS(RAB!$F$14:$F$80,RAB!$C$14:$C$80,C723) -> 0 | E723: =IF(D723=0,0,1) -> 0 | F723: =IF(D723=0,0,SUM($E$713:E723)) -> 0
B724: 11 | C724: =IF(ISERROR(OFFSET('HARGA SATUAN'!$C$6,MATCH(B724,'HARGA SATUAN'!$N$7:$N$1492,0),0)),"",OFFSET('HARGA SATUAN'!$C$6,MATCH(B724,'HARGA SATUAN'!$N$7:$N$1492,0),0)) -> MCB 1 Fasa 10 A | D724: =SUMIFS(RAB!$F$14:$F$80,RAB!$C$14:$C$80,C724) -> 0 | E724: =IF(D724=0,0,1) -> 0 | F724: =IF(D724=0,0,SUM($E$713:E724)) -> 0
B725: 12 | C725: =IF(ISERROR(OFFSET('HARGA SATUAN'!$C$6,MATCH(B725,'HARGA SATUAN'!$N$7:$N$1492,0),0)),"",OFFSET('HARGA SATUAN'!$C$6,MATCH(B725,'HARGA SATUAN'!$N$7:$N$1492,0),0)) -> MCB 1 Fasa 16 A | D725: =SUMIFS(RAB!$F$14:$F$80,RAB!$C$14:$C$80,C725) -> 0 | E725: =IF(D725=0,0,1) -> 0 | F725: =IF(D725=0,0,SUM($E$713:E725)) -> 0
... B1320: 607 | C1320: =IF(ISERROR(OFFSET('HARGA SATUAN'!$C$6,MATCH(B1320,'HARGA SATUAN'!$N$7:$N$1492,0),0)),"",OFFSET('HARGA SATUAN'!$C$6,MATCH(B1320,'HARGA SATUAN'!$N$7:$N$1492,0),0)) | D1320: =SUMIFS(RAB!$F$14:$F$80,RAB!$C$14:$C$80,C1320) -> 0 | E1320: =IF(D1320=0,0,1) -> 0 | F1320: =IF(D1320=0,0,SUM($E$713:E1320)) -> 0

Sheet REKAP TIANG
C1: =RAB!C1 -> PT. PLN ( PERSERO )
C2: =RAB!C2 -> UNIT INDUK DISTRIBUSI JAWA TENGAH & DI YOGYAKARTA
C3: =RAB!C3 -> UP3 DEMAK
B4: REKAP KEBUTUHAN TIANG
E6: Pekerjaan | F6: : | G6: =RAB!G6 -> RACHMAT SARWONO
E7: Lokasi | F7: : | G7: =RAB!G7 -> DS PURWOSARI, KEC SAYUNG
E8: Pelaksana | F8: : | G8: =RAB!G8 -> UP3 DEMAK
E9: Anggaran | F9: : | G9: =RAB!G9 -> SAR 2023
B11: NO | C11: URAIAN | D11: GOL | E11: SAT | F11: VOL | G11: HARGA SATUAN | H11: BIAYA YANG DIPERLUKAN ( Rp )
H12: MDU | I12: HARDWARE | J12: JASA | K12: JUMLAH
G14: =IF(ISERROR(OFFSET('HARGA SATUAN'!$I$6,MATCH(C14,'HARGA SATUAN'!$C$7:$C$1492,0),0)),"",OFFSET('HARGA SATUAN'!$I$6,MATCH(C14,'HARGA SATUAN'!$C$7:$C$1492,0),0)) | H14: =IF(OR(D14="MDU",D14="MDU-KD"),G14*F14,0) -> 0 | I14: =IF(D14="HDW",G14*F14,0) -> 0 | J14: =IF(D14="JASA",G14*F14,0) -> 0 | K14: =SUM(H14:J14) -> 0
B15: + | C15: REKAP TIANG | G15: =IF(ISERROR(OFFSET('HARGA SATUAN'!$I$6,MATCH(C15,'HARGA SATUAN'!$C$7:$C$1492,0),0)),"",OFFSET('HARGA SATUAN'!$I$6,MATCH(C15,'HARGA SATUAN'!$C$7:$C$1492,0),0)) | H15: =IF(OR(D15="MDU",D15="MDU-KD"),G15*F15,0) -> 0 | I15: =IF(D15="HDW",G15*F15,0) -> 0 | J15: =IF(D15="JASA",G15*F15,0) -> 0 | K15: =SUM(H15:J15) -> 0
A16: 1 | B16: =IF(C16="","",A16) -> 1 | C16: =IF(ISERROR(OFFSET($C$56,MATCH(A16,$F$57:$F$76,0),0)),"",OFFSET($C$56,MATCH(A16,$F$57:$F$76,0),0)) -> Tiang Beton 9M-200 daN+E | D16: =IF(ISERROR(OFFSET('HARGA SATUAN'!$D$6,MATCH(C16,'HARGA SATUAN'!$C$7:$C$1492,0),0)),"",OFFSET('HARGA SATUAN'!$D$6,MATCH(C16,'HARGA SATUAN'!$C$7:$C$1492,0),0)) -> HDW | E16: =IF(B16="+","Unit",IF(ISERROR(OFFSET('HARGA SATUAN'!$E$6,MATCH(C16,'HARGA SATUAN'!$C$7:$C$1492,0),0)),"",OFFSET('HARGA SATUAN'!$E$6,MATCH(C16,'HARGA SATUAN'!$C$7:$C$1492,0),0))) -> Btg | F16: =IF(ISERROR(OFFSET($D$56,MATCH(A16,$F$57:$F$76,0),0)),"",OFFSET($D$56,MATCH(A16,$F$57:$F$76,0),0)) -> 1 | G16: =IF(ISERROR(OFFSET('HARGA SATUAN'!$I$6,MATCH(C16,'HARGA SATUAN'!$C$7:$C$1492,0),0)),"",OFFSET('HARGA SATUAN'!$I$6,MATCH(C16,'HARGA SATUAN'!$C$7:$C$1492,0),0)) -> 3382600 | H16: =IF(OR(D16="MDU",D16="MDU-KD"),G16*F16,0) -> 0 | I16: =IF(D16="HDW",G16*F16,0) -> 3382600 | J16: =IF(D16="JASA",G16*F16,0) -> 0 | K16: =SUM(H16:J16) -> 3382600
A17: 2 | B17: =IF(C17="","",A17) | C17: =IF(ISERROR(OFFSET($C$56,MATCH(A17,$F$57:$F$76,0),0)),"",OFFSET($C$56,MATCH(A17,$F$57:$F$76,0),0)) | D17: =IF(ISERROR(OFFSET('HARGA SATUAN'!$D$6,MATCH(C17,'HARGA SATUAN'!$C$7:$C$1492,0),0)),"",OFFSET('HARGA SATUAN'!$D$6,MATCH(C17,'HARGA SATUAN'!$C$7:$C$1492,0),0)) | E17: =IF(B17="+","Unit",IF(ISERROR(OFFSET('HARGA SATUAN'!$E$6,MATCH(C17,'HARGA SATUAN'!$C$7:$C$1492,0),0)),"",OFFSET('HARGA SATUAN'!$E$6,MATCH(C17,'HARGA SATUAN'!$C$7:$C$1492,0),0))) -> 0 | F17: =IF(ISERROR(OFFSET($D$56,MATCH(A17,$F$57:$F$76,0),0)),"",OFFSET($D$56,MATCH(A17,$F$57:$F$76,0),0)) | G17: =IF(ISERROR(OFFSET('HARGA SATUAN'!$I$6,MATCH(C17,'HARGA SATUAN'!$C$7:$C$1492,0),0)),"",OFFSET('HARGA SATUAN'!$I$6,MATCH(C17,'HARGA SATUAN'!$C$7:$C$1492,0),0)) -> 0 | H17: =IF(OR(D17="MDU",D17="MDU-KD"),G17*F17,0) -> 0 | I17: =IF(D17="HDW",G17*F17,0) -> 0 | J17: =IF(D17="JASA",G17*F17,0) -> 0 | K17: =SUM(H17:J17) -> 0
A18: 3 | B18: =IF(C18="","",A18) | C18: =IF(ISERROR(OFFSET($C$56,MATCH(A18,$F$57:$F$76,0),0)),"",OFFSET($C$56,MATCH(A18,$F$57:$F$76,0),0)) | D18: =IF(ISERROR(OFFSET('HARGA SATUAN'!$D$6,MATCH(C18,'HARGA SATUAN'!$C$7:$C$1492,0),0)),"",OFFSET('HARGA SATUAN'!$D$6,MATCH(C18,'HARGA SATUAN'!$C$7:$C$1492,0),0)) | E18: =IF(B18="+","Unit",IF(ISERROR(OFFSET('HARGA SATUAN'!$E$6,MATCH(C18,'HARGA SATUAN'!$C$7:$C$1492,0),0)),"",OFFSET('HARGA SATUAN'!$E$6,MATCH(C18,'HARGA SATUAN'!$C$7:$C$1492,0),0))) -> 0 | F18: =IF(ISERROR(OFFSET($D$56,MATCH(A18,$F$57:$F$76,0),0)),"",OFFSET($D$56,MATCH(A18,$F$57:$F$76,0),0)) | G18: =IF(ISERROR(OFFSET('HARGA SATUAN'!$I$6,MATCH(C18,'HARGA SATUAN'!$C$7:$C$1492,0),0)),"",OFFSET('HARGA SATUAN'!$I$6,MATCH(C18,'HARGA SATUAN'!$C$7:$C$1492,0),0)) -> 0 | H18: =IF(OR(D18="MDU",D18="MDU-KD"),G18*F18,0) -> 0 | I18: =IF(D18="HDW",G18*F18,0) -> 0 | J18: =IF(D18="JASA",G18*F18,0) -> 0 | K18: =SUM(H18:J18) -> 0
A19: 4 | B19: =IF(C19="","",A19) | C19: =IF(ISERROR(OFFSET($C$56,MATCH(A19,$F$57:$F$76,0),0)),"",OFFSET($C$56,MATCH(A19,$F$57:$F$76,0),0)) | D19: =IF(ISERROR(OFFSET('HARGA SATUAN'!$D$6,MATCH(C19,'HARGA SATUAN'!$C$7:$C$1492,0),0)),"",OFFSET('HARGA SATUAN'!$D$6,MATCH(C19,'HARGA SATUAN'!$C$7:$C$1492,0),0)) | E19: =IF(B19="+","Unit",IF(ISERROR(OFFSET('HARGA SATUAN'!$E$6,MATCH(C19,'HARGA SATUAN'!$C$7:$C$1492,0),0)),"",OFFSET('HARGA SATUAN'!$E$6,MATCH(C19,'HARGA SATUAN'!$C$7:$C$1492,0),0))) -> 0 | F19: =IF(ISERROR(OFFSET($D$56,MATCH(A19,$F$57:$F$76,0),0)),"",OFFSET($D$56,MATCH(A19,$F$57:$F$76,0),0)) | G19: =IF(ISERROR(OFFSET('HARGA SATUAN'!$I$6,MATCH(C19,'HARGA SATUAN'!$C$7:$C$1492,0),0)),"",OFFSET('HARGA SATUAN'!$I$6,MATCH(C19,'HARGA SATUAN'!$C$7:$C$1492,0),0)) -> 0 | H19: =IF(OR(D19="MDU",D19="MDU-KD"),G19*F19,0) -> 0 | I19: =IF(D19="HDW",G19*F19,0) -> 0 | J19: =IF(D19="JASA",G19*F19,0) -> 0 | K19: =SUM(H19:J19) -> 0
A20: 5 | B20: =IF(C20="","",A20) | C20: =IF(ISERROR(OFFSET($C$56,MATCH(A20,$F$57:$F$76,0),0)),"",OFFSET($C$56,MATCH(A20,$F$57:$F$76,0),0)) | D20: =IF(ISERROR(OFFSET('HARGA SATUAN'!$D$6,MATCH(C20,'HARGA SATUAN'!$C$7:$C$1492,0),0)),"",OFFSET('HARGA SATUAN'!$D$6,MATCH(C20,'HARGA SATUAN'!$C$7:$C$1492,0),0)) | E20: =IF(B20="+","Unit",IF(ISERROR(OFFSET('HARGA SATUAN'!$E$6,MATCH(C20,'HARGA SATUAN'!$C$7:$C$1492,0),0)),"",OFFSET('HARGA SATUAN'!$E$6,MATCH(C20,'HARGA SATUAN'!$C$7:$C$1492,0),0))) -> 0 | F20: =IF(ISERROR(OFFSET($D$56,MATCH(A20,$F$57:$F$76,0),0)),"",OFFSET($D$56,MATCH(A20,$F$57:$F$76,0),0)) | G20: =IF(ISERROR(OFFSET('HARGA SATUAN'!$I$6,MATCH(C20,'HARGA SATUAN'!$C$7:$C$1492,0),0)),"",OFFSET('HARGA SATUAN'!$I$6,MATCH(C20,'HARGA SATUAN'!$C$7:$C$1492,0),0)) -> 0 | H20: =IF(OR(D20="MDU",D20="MDU-KD"),G20*F20,0) -> 0 | I20: =IF(D20="HDW",G20*F20,0) -> 0 | J20: =IF(D20="JASA",G20*F20,0) -> 0 | K20: =SUM(H20:J20) -> 0
A21: 6 | B21: =IF(C21="","",A21) | C21: =IF(ISERROR(OFFSET($C$56,MATCH(A21,$F$57:$F$76,0),0)),"",OFFSET($C$56,MATCH(A21,$F$57:$F$76,0),0)) | D21: =IF(ISERROR(OFFSET('HARGA SATUAN'!$D$6,MATCH(C21,'HARGA SATUAN'!$C$7:$C$1492,0),0)),"",OFFSET('HARGA SATUAN'!$D$6,MATCH(C21,'HARGA SATUAN'!$C$7:$C$1492,0),0)) | E21: =IF(B21="+","Unit",IF(ISERROR(OFFSET('HARGA SATUAN'!$E$6,MATCH(C21,'HARGA SATUAN'!$C$7:$C$1492,0),0)),"",OFFSET('HARGA SATUAN'!$E$6,MATCH(C21,'HARGA SATUAN'!$C$7:$C$1492,0),0))) -> 0 | F21: =IF(ISERROR(OFFSET($D$56,MATCH(A21,$F$57:$F$76,0),0)),"",OFFSET($D$56,MATCH(A21,$F$57:$F$76,0),0)) | G21: =IF(ISERROR(OFFSET('HARGA SATUAN'!$I$6,MATCH(C21,'HARGA SATUAN'!$C$7:$C$1492,0),0)),"",OFFSET('HARGA SATUAN'!$I$6,MATCH(C21,'HARGA SATUAN'!$C$7:$C$1492,0),0)) -> 0 | H21: =IF(OR(D21="MDU",D21="MDU-KD"),G21*F21,0) -> 0 | I21: =IF(D21="HDW",G21*F21,0) -> 0 | J21: =IF(D21="JASA",G21*F21,0) -> 0 | K21: =SUM(H21:J21) -> 0
A22: 7 | B22: =IF(C22="","",A22) | C22: =IF(ISERROR(OFFSET($C$56,MATCH(A22,$F$57:$F$76,0),0)),"",OFFSET($C$56,MATCH(A22,$F$57:$F$76,0),0)) | D22: =IF(ISERROR(OFFSET('HARGA SATUAN'!$D$6,MATCH(C22,'HARGA SATUAN'!$C$7:$C$1492,0),0)),"",OFFSET('HARGA SATUAN'!$D$6,MATCH(C22,'HARGA SATUAN'!$C$7:$C$1492,0),0)) | E22: =IF(B22="+","Unit",IF(ISERROR(OFFSET('HARGA SATUAN'!$E$6,MATCH(C22,'HARGA SATUAN'!$C$7:$C$1492,0),0)),"",OFFSET('HARGA SATUAN'!$E$6,MATCH(C22,'HARGA SATUAN'!$C$7:$C$1492,0),0))) -> 0 | F22: =IF(ISERROR(OFFSET($D$56,MATCH(A22,$F$57:$F$76,0),0)),"",OFFSET($D$56,MATCH(A22,$F$57:$F$76,0),0)) | G22: =IF(ISERROR(OFFSET('HARGA SATUAN'!$I$6,MATCH(C22,'HARGA SATUAN'!$C$7:$C$1492,0),0)),"",OFFSET('HARGA SATUAN'!$I$6,MATCH(C22,'HARGA SATUAN'!$C$7:$C$1492,0),0)) -> 0 | H22: =IF(OR(D22="MDU",D22="MDU-KD"),G22*F22,0) -> 0 | I22: =IF(D22="HDW",G22*F22,0) -> 0 | J22: =IF(D22="JASA",G22*F22,0) -> 0 | K22: =SUM(H22:J22) -> 0
A23: 8 | B23: =IF(C23="","",A23) | C23: =IF(ISERROR(OFFSET($C$56,MATCH(A23,$F$57:$F$76,0),0)),"",OFFSET($C$56,MATCH(A23,$F$57:$F$76,0),0)) | D23: =IF(ISERROR(OFFSET('HARGA SATUAN'!$D$6,MATCH(C23,'HARGA SATUAN'!$C$7:$C$1492,0),0)),"",OFFSET('HARGA SATUAN'!$D$6,MATCH(C23,'HARGA SATUAN'!$C$7:$C$1492,0),0)) | E23: =IF(B23="+","Unit",IF(ISERROR(OFFSET('HARGA SATUAN'!$E$6,MATCH(C23,'HARGA SATUAN'!$C$7:$C$1492,0),0)),"",OFFSET('HARGA SATUAN'!$E$6,MATCH(C23,'HARGA SATUAN'!$C$7:$C$1492,0),0))) -> 0 | F23: =IF(ISERROR(OFFSET($D$56,MATCH(A23,$F$57:$F$76,0),0)),"",OFFSET($D$56,MATCH(A23,$F$57:$F$76,0),0)) | G23: =IF(ISERROR(OFFSET('HARGA SATUAN'!$I$6,MATCH(C23,'HARGA SATUAN'!$C$7:$C$1492,0),0)),"",OFFSET('HARGA SATUAN'!$I$6,MATCH(C23,'HARGA SATUAN'!$C$7:$C$1492,0),0)) -> 0 | H23: =IF(OR(D23="MDU",D23="MDU-KD"),G23*F23,0) -> 0 | I23: =IF(D23="HDW",G23*F23,0) -> 0 | J23: =IF(D23="JASA",G23*F23,0) -> 0 | K23: =SUM(H23:J23) -> 0
A24: 9 | B24: =IF(C24="","",A24) | C24: =IF(ISERROR(OFFSET($C$56,MATCH(A24,$F$57:$F$76,0),0)),"",OFFSET($C$56,MATCH(A24,$F$57:$F$76,0),0)) | D24: =IF(ISERROR(OFFSET('HARGA SATUAN'!$D$6,MATCH(C24,'HARGA SATUAN'!$C$7:$C$1492,0),0)),"",OFFSET('HARGA SATUAN'!$D$6,MATCH(C24,'HARGA SATUAN'!$C$7:$C$1492,0),0)) | E24: =IF(B24="+","Unit",IF(ISERROR(OFFSET('HARGA SATUAN'!$E$6,MATCH(C24,'HARGA SATUAN'!$C$7:$C$1492,0),0)),"",OFFSET('HARGA SATUAN'!$E$6,MATCH(C24,'HARGA SATUAN'!$C$7:$C$1492,0),0))) -> 0 | F24: =IF(ISERROR(OFFSET($D$56,MATCH(A24,$F$57:$F$76,0),0)),"",OFFSET($D$56,MATCH(A24,$F$57:$F$76,0),0)) | G24: =IF(ISERROR(OFFSET('HARGA SATUAN'!$I$6,MATCH(C24,'HARGA SATUAN'!$C$7:$C$1492,0),0)),"",OFFSET('HARGA SATUAN'!$I$6,MATCH(C24,'HARGA SATUAN'!$C$7:$C$1492,0),0)) -> 0 | H24: =IF(OR(D24="MDU",D24="MDU-KD"),G24*F24,0) -> 0 | I24: =IF(D24="HDW",G24*F24,0) -> 0 | J24: =IF(D24="JASA",G24*F24,0) -> 0 | K24: =SUM(H24:J24) -> 0
A25: 10 | B25: =IF(C25="","",A25) | C25: =IF(ISERROR(OFFSET($C$56,MATCH(A25,$F$57:$F$76,0),0)),"",OFFSET($C$56,MATCH(A25,$F$57:$F$76,0),0)) | D25: =IF(ISERROR(OFFSET('HARGA SATUAN'!$D$6,MATCH(C25,'HARGA SATUAN'!$C$7:$C$1492,0),0)),"",OFFSET('HARGA SATUAN'!$D$6,MATCH(C25,'HARGA SATUAN'!$C$7:$C$1492,0),0)) | E25: =IF(B25="+","Unit",IF(ISERROR(OFFSET('HARGA SATUAN'!$E$6,MATCH(C25,'HARGA SATUAN'!$C$7:$C$1492,0),0)),"",OFFSET('HARGA SATUAN'!$E$6,MATCH(C25,'HARGA SATUAN'!$C$7:$C$1492,0),0))) -> 0 | F25: =IF(ISERROR(OFFSET($D$56,MATCH(A25,$F$57:$F$76,0),0)),"",OFFSET($D$56,MATCH(A25,$F$57:$F$76,0),0)) | G25: =IF(ISERROR(OFFSET('HARGA SATUAN'!$I$6,MATCH(C25,'HARGA SATUAN'!$C$7:$C$1492,0),0)),"",OFFSET('HARGA SATUAN'!$I$6,MATCH(C25,'HARGA SATUAN'!$C$7:$C$1492,0),0)) -> 0 | H25: =IF(OR(D25="MDU",D25="MDU-KD"),G25*F25,0) -> 0 | I25: =IF(D25="HDW",G25*F25,0) -> 0 | J25: =IF(D25="JASA",G25*F25,0) -> 0 | K25: =SUM(H25:J25) -> 0
A26: 11 | B26: =IF(C26="","",A26) | C26: =IF(ISERROR(OFFSET($C$56,MATCH(A26,$F$57:$F$76,0),0)),"",OFFSET($C$56,MATCH(A26,$F$57:$F$76,0),0)) | D26: =IF(ISERROR(OFFSET('HARGA SATUAN'!$D$6,MATCH(C26,'HARGA SATUAN'!$C$7:$C$1492,0),0)),"",OFFSET('HARGA SATUAN'!$D$6,MATCH(C26,'HARGA SATUAN'!$C$7:$C$1492,0),0)) | E26: =IF(B26="+","Unit",IF(ISERROR(OFFSET('HARGA SATUAN'!$E$6,MATCH(C26,'HARGA SATUAN'!$C$7:$C$1492,0),0)),"",OFFSET('HARGA SATUAN'!$E$6,MATCH(C26,'HARGA SATUAN'!$C$7:$C$1492,0),0))) -> 0 | F26: =IF(ISERROR(OFFSET($D$56,MATCH(A26,$F$57:$F$76,0),0)),"",OFFSET($D$56,MATCH(A26,$F$57:$F$76,0),0)) | G26: =IF(ISERROR(OFFSET('HARGA SATUAN'!$I$6,MATCH(C26,'HARGA SATUAN'!$C$7:$C$1492,0),0)),"",OFFSET('HARGA SATUAN'!$I$6,MATCH(C26,'HARGA SATUAN'!$C$7:$C$1492,0),0)) -> 0 | H26: =IF(OR(D26="MDU",D26="MDU-KD"),G26*F26,0) -> 0 | I26: =IF(D26="HDW",G26*F26,0) -> 0 | J26: =IF(D26="JASA",G26*F26,0) -> 0 | K26: =SUM(H26:J26) -> 0
A27: 12 | B27: =IF(C27="","",A27) | C27: =IF(ISERROR(OFFSET($C$56,MATCH(A27,$F$57:$F$76,0),0)),"",OFFSET($C$56,MATCH(A27,$F$57:$F$76,0),0)) | D27: =IF(ISERROR(OFFSET('HARGA SATUAN'!$D$6,MATCH(C27,'HARGA SATUAN'!$C$7:$C$1492,0),0)),"",OFFSET('HARGA SATUAN'!$D$6,MATCH(C27,'HARGA SATUAN'!$C$7:$C$1492,0),0)) | E27: =IF(B27="+","Unit",IF(ISERROR(OFFSET('HARGA SATUAN'!$E$6,MATCH(C27,'HARGA SATUAN'!$C$7:$C$1492,0),0)),"",OFFSET('HARGA SATUAN'!$E$6,MATCH(C27,'HARGA SATUAN'!$C$7:$C$1492,0),0))) -> 0 | F27: =IF(ISERROR(OFFSET($D$56,MATCH(A27,$F$57:$F$76,0),0)),"",OFFSET($D$56,MATCH(A27,$F$57:$F$76,0),0)) | G27: =IF(ISERROR(OFFSET('HARGA SATUAN'!$I$6,MATCH(C27,'HARGA SATUAN'!$C$7:$C$1492,0),0)),"",OFFSET('HARGA SATUAN'!$I$6,MATCH(C27,'HARGA SATUAN'!$C$7:$C$1492,0),0)) -> 0 | H27: =IF(OR(D27="MDU",D27="MDU-KD"),G27*F27,0) -> 0 | I27: =IF(D27="HDW",G27*F27,0) -> 0 | J27: =IF(D27="JASA",G27*F27,0) -> 0 | K27: =SUM(H27:J27) -> 0
... A35: 20 | B35: =IF(C35="","",A35) | C35: =IF(ISERROR(OFFSET($C$56,MATCH(A35,$F$57:$F$76,0),0)),"",OFFSET($C$56,MATCH(A35,$F$57:$F$76,0),0)) | D35: =IF(ISERROR(OFFSET('HARGA SATUAN'!$D$6,MATCH(C35,'HARGA SATUAN'!$C$7:$C$1492,0),0)),"",OFFSET('HARGA SATUAN'!$D$6,MATCH(C35,'HARGA SATUAN'!$C$7:$C$1492,0),0)) | E35: =IF(B35="+","Unit",IF(ISERROR(OFFSET('HARGA SATUAN'!$E$6,MATCH(C35,'HARGA SATUAN'!$C$7:$C$1492,0),0)),"",OFFSET('HARGA SATUAN'!$E$6,MATCH(C35,'HARGA SATUAN'!$C$7:$C$1492,0),0))) -> 0 | F35: =IF(ISERROR(OFFSET($D$56,MATCH(A35,$F$57:$F$76,0),0)),"",OFFSET($D$56,MATCH(A35,$F$57:$F$76,0),0)) | G35: =IF(ISERROR(OFFSET('HARGA SATUAN'!$I$6,MATCH(C35,'HARGA SATUAN'!$C$7:$C$1492,0),0)),"",OFFSET('HARGA SATUAN'!$I$6,MATCH(C35,'HARGA SATUAN'!$C$7:$C$1492,0),0)) -> 0 | H35: =IF(OR(D35="MDU",D35="MDU-KD"),G35*F35,0) -> 0 | I35: =IF(D35="HDW",G35*F35,0) -> 0 | J35: =IF(D35="JASA",G35*F35,0) -> 0 | K35: =SUM(H35:J35) -> 0
D36: =IF(ISERROR(OFFSET('HARGA SATUAN'!$D$6,MATCH(C36,'HARGA SATUAN'!$C$7:$C$1492,0),0)),"",OFFSET('HARGA SATUAN'!$D$6,MATCH(C36,'HARGA SATUAN'!$C$7:$C$1492,0),0)) | E36: =IF(B36="+","Unit",IF(ISERROR(OFFSET('HARGA SATUAN'!$E$6,MATCH(C36,'HARGA SATUAN'!$C$7:$C$1492,0),0)),"",OFFSET('HARGA SATUAN'!$E$6,MATCH(C36,'HARGA SATUAN'!$C$7:$C$1492,0),0))) | F36: =IF(ISERROR(OFFSET($D$56,MATCH(A36,$F$57:$F$76,0),0)),"",OFFSET($D$56,MATCH(A36,$F$57:$F$76,0),0)) -> 0 | G36: =IF(ISERROR(OFFSET('HARGA SATUAN'!$I$6,MATCH(C36,'HARGA SATUAN'!$C$7:$C$1492,0),0)),"",OFFSET('HARGA SATUAN'!$I$6,MATCH(C36,'HARGA SATUAN'!$C$7:$C$1492,0),0)) | H36: =IF(OR(D36="MDU",D36="MDU-KD"),G36*F36,0) -> 0 | I36: =IF(D36="HDW",G36*F36,0) -> 0 | J36: =IF(D36="JASA",G36*F36,0) -> 0 | K36: =SUM(H36:J36) -> 0
C38: Jumlah MDU - Hardware - Jasa | G38: : | H38: =SUM(H14:H37) -> 0 | I38: =SUM(I14:I37) -> 3382600 | J38: =SUM(J14:J37) -> 0 | K38: =SUM(K14:K37) -> 3382600
C39: PPN 10% | G39: : | H39: =H38*0.1 -> 0 | I39: =I38*0.1 -> 338260 | J39: =J38*0.1 -> 0 | K39: =K38*0.1 -> 338260
C40: Jumlah Total | G40: : | H40: =SUM(H38:H39) -> 0 | I40: =SUM(I38:I39) -> 3720860 | J40: =SUM(J38:J39) -> 0 | K40: =SUM(K38:K39) -> 3720860
B41: ="Terbilang : ( "&L42&" Rupiah )" -> #NAME?
L42: =PROPER([91]!terbilang(K40)) -> #NAME?
B43: ="Harga yang dipakai adalah "&'HARGA SATUAN'!I5&"" -> Harga yang dipakai adalah RAB HSS 2023
B56: NO | C56: JENIS TIANG
B57: 1 | C57: =IF(ISERROR(OFFSET('HARGA SATUAN'!$C$6,MATCH('REKAP TIANG'!B57,'HARGA SATUAN'!$P$7:$P$1455,0),0)),"",OFFSET('HARGA SATUAN'!$C$6,MATCH('REKAP TIANG'!B57,'HARGA SATUAN'!$P$7:$P$1455,0),0)) -> Tiang Beton 9M-200 daN+E | D57: =SUMIFS(RAB!$F$14:$F$80,RAB!$C$14:$C$80,'REKAP TIANG'!C57) -> 1 | E57: =IF(D57=0,0,1) -> 1 | F57: =IF(D57=0,0,SUM($E$56:E57)) -> 1
B58: 2 | C58: =IF(ISERROR(OFFSET('HARGA SATUAN'!$C$6,MATCH('REKAP TIANG'!B58,'HARGA SATUAN'!$P$7:$P$1455,0),0)),"",OFFSET('HARGA SATUAN'!$C$6,MATCH('REKAP TIANG'!B58,'HARGA SATUAN'!$P$7:$P$1455,0),0)) -> Tiang Beton 11M-200 daN+E | D58: =SUMIFS(RAB!$F$14:$F$80,RAB!$C$14:$C$80,'REKAP TIANG'!C58) -> 0 | E58: =IF(D58=0,0,1) -> 0 | F58: =IF(D58=0,0,SUM($E$56:E58)) -> 0
B59: 3 | C59: =IF(ISERROR(OFFSET('HARGA SATUAN'!$C$6,MATCH('REKAP TIANG'!B59,'HARGA SATUAN'!$P$7:$P$1455,0),0)),"",OFFSET('HARGA SATUAN'!$C$6,MATCH('REKAP TIANG'!B59,'HARGA SATUAN'!$P$7:$P$1455,0),0)) -> Tiang Beton 12M-200 daN+E | D59: =SUMIFS(RAB!$F$14:$F$80,RAB!$C$14:$C$80,'REKAP TIANG'!C59) -> 0 | E59: =IF(D59=0,0,1) -> 0 | F59: =IF(D59=0,0,SUM($E$56:E59)) -> 0
B60: 4 | C60: =IF(ISERROR(OFFSET('HARGA SATUAN'!$C$6,MATCH('REKAP TIANG'!B60,'HARGA SATUAN'!$P$7:$P$1455,0),0)),"",OFFSET('HARGA SATUAN'!$C$6,MATCH('REKAP TIANG'!B60,'HARGA SATUAN'!$P$7:$P$1455,0),0)) -> Tiang Beton 12M-350 daN+E | D60: =SUMIFS(RAB!$F$14:$F$80,RAB!$C$14:$C$80,'REKAP TIANG'!C60) -> 0 | E60: =IF(D60=0,0,1) -> 0 | F60: =IF(D60=0,0,SUM($E$56:E60)) -> 0
B61: 5 | C61: =IF(ISERROR(OFFSET('HARGA SATUAN'!$C$6,MATCH('REKAP TIANG'!B61,'HARGA SATUAN'!$P$7:$P$1455,0),0)),"",OFFSET('HARGA SATUAN'!$C$6,MATCH('REKAP TIANG'!B61,'HARGA SATUAN'!$P$7:$P$1455,0),0)) -> Tiang Beton 13M-350 daN+E | D61: =SUMIFS(RAB!$F$14:$F$80,RAB!$C$14:$C$80,'REKAP TIANG'!C61) -> 0 | E61: =IF(D61=0,0,1) -> 0 | F61: =IF(D61=0,0,SUM($E$56:E61)) -> 0
B62: 6 | C62: =IF(ISERROR(OFFSET('HARGA SATUAN'!$C$6,MATCH('REKAP TIANG'!B62,'HARGA SATUAN'!$P$7:$P$1455,0),0)),"",OFFSET('HARGA SATUAN'!$C$6,MATCH('REKAP TIANG'!B62,'HARGA SATUAN'!$P$7:$P$1455,0),0)) -> Tiang Beton 14M-350 daN+E | D62: =SUMIFS(RAB!$F$14:$F$80,RAB!$C$14:$C$80,'REKAP TIANG'!C62) -> 0 | E62: =IF(D62=0,0,1) -> 0 | F62: =IF(D62=0,0,SUM($E$56:E62)) -> 0
B63: 7 | C63: =IF(ISERROR(OFFSET('HARGA SATUAN'!$C$6,MATCH('REKAP TIANG'!B63,'HARGA SATUAN'!$P$7:$P$1455,0),0)),"",OFFSET('HARGA SATUAN'!$C$6,MATCH('REKAP TIANG'!B63,'HARGA SATUAN'!$P$7:$P$1455,0),0)) | D63: =SUMIFS(RAB!$F$14:$F$80,RAB!$C$14:$C$80,'REKAP TIANG'!C63) -> 0 | E63: =IF(D63=0,0,1) -> 0 | F63: =IF(D63=0,0,SUM($E$56:E63)) -> 0
...

Sheet REKAP MDU
C1: =RAB!C1 -> PT. PLN ( PERSERO )
C2: =RAB!C2 -> UNIT INDUK DISTRIBUSI JAWA TENGAH & DI YOGYAKARTA
C3: =RAB!C3 -> UP3 DEMAK
B4: REKAP MDU
E6: Pekerjaan | F6: : | G6: =RAB!G6 -> RACHMAT SARWONO
E7: Lokasi | F7: : | G7: =RAB!G7 -> DS PURWOSARI, KEC SAYUNG
E8: Pelaksana | F8: : | G8: =RAB!G8 -> UP3 DEMAK
E9: Anggaran | F9: : | G9: =RAB!G9 -> SAR 2023
B11: NO | C11: URAIAN | D11: GOL | E11: SAT | F11: VOL | G11: HARGA SATUAN | H11: BIAYA YANG DIPERLUKAN ( Rp )
H12: MDU | I12: HARDWARE | J12: JASA | K12: JUMLAH
G14: =IF(ISERROR(OFFSET('HARGA SATUAN'!$I$6,MATCH(C14,'HARGA SATUAN'!$C$7:$C$1492,0),0)),"",OFFSET('HARGA SATUAN'!$I$6,MATCH(C14,'HARGA SATUAN'!$C$7:$C$1492,0),0)) | H14: =IF(OR(D14="MDU",D14="MDU-KD"),G14*F14,0) -> 0 | I14: =IF(D14="HDW",G14*F14,0) -> 0 | J14: =IF(D14="JASA",G14*F14,0) -> 0 | K14: =SUM(H14:J14) -> 0
B15: + | C15: REKAP MDU | G15: =IF(ISERROR(OFFSET('HARGA SATUAN'!$I$6,MATCH(C15,'HARGA SATUAN'!$C$7:$C$1492,0),0)),"",OFFSET('HARGA SATUAN'!$I$6,MATCH(C15,'HARGA SATUAN'!$C$7:$C$1492,0),0)) | H15: =IF(OR(D15="MDU",D15="MDU-KD"),G15*F15,0) -> 0 | I15: =IF(D15="HDW",G15*F15,0) -> 0 | J15: =IF(D15="JASA",G15*F15,0) -> 0 | K15: =SUM(H15:J15) -> 0
A16: 1 | B16: =IF(C16="","",A16) -> 1 | C16: =IF(ISERROR(OFFSET($C$223,MATCH(A16,$F$224:$F$373,0),0)),"",OFFSET($C$223,MATCH(A16,$F$224:$F$373,0),0)) -> KWH Elektronik; 3P; 4W; 220/380V; 5(80) A; kls 1 (Pengukuran Langsung) | D16: =IF(ISERROR(OFFSET('HARGA SATUAN'!$D$6,MATCH(C16,'HARGA SATUAN'!$C$7:$C$1492,0),0)),"",OFFSET('HARGA SATUAN'!$D$6,MATCH(C16,'HARGA SATUAN'!$C$7:$C$1492,0),0)) -> MDU-KD | E16: =IF(B16="+","Unit",IF(ISERROR(OFFSET('HARGA SATUAN'!$E$6,MATCH(C16,'HARGA SATUAN'!$C$7:$C$1492,0),0)),"",OFFSET('HARGA SATUAN'!$E$6,MATCH(C16,'HARGA SATUAN'!$C$7:$C$1492,0),0))) -> Bh | F16: =IF(ISERROR(OFFSET($D$223,MATCH(A16,$F$224:$F$373,0),0)),"",OFFSET($D$223,MATCH(A16,$F$224:$F$373,0),0)) -> 1 | G16: =IF(ISERROR(OFFSET('HARGA SATUAN'!$I$6,MATCH(C16,'HARGA SATUAN'!$C$7:$C$1492,0),0)),"",OFFSET('HARGA SATUAN'!$I$6,MATCH(C16,'HARGA SATUAN'!$C$7:$C$1492,0),0)) -> 1427400 | H16: =IF(OR(D16="MDU",D16="MDU-KD"),G16*F16,0) -> 1427400 | I16: =IF(D16="HDW",G16*F16,0) -> 0 | J16: =IF(D16="JASA",G16*F16,0) -> 0 | K16: =SUM(H16:J16) -> 1427400
A17: 2 | B17: =IF(C17="","",A17) -> 2 | C17: =IF(ISERROR(OFFSET($C$223,MATCH(A17,$F$224:$F$373,0),0)),"",OFFSET($C$223,MATCH(A17,$F$224:$F$373,0),0)) -> Smart Box Langsung Daya 13.2 kVA MCCB 20 A | D17: =IF(ISERROR(OFFSET('HARGA SATUAN'!$D$6,MATCH(C17,'HARGA SATUAN'!$C$7:$C$1492,0),0)),"",OFFSET('HARGA SATUAN'!$D$6,MATCH(C17,'HARGA SATUAN'!$C$7:$C$1492,0),0)) -> MDU-KD | E17: =IF(B17="+","Unit",IF(ISERROR(OFFSET('HARGA SATUAN'!$E$6,MATCH(C17,'HARGA SATUAN'!$C$7:$C$1492,0),0)),"",OFFSET('HARGA SATUAN'!$E$6,MATCH(C17,'HARGA SATUAN'!$C$7:$C$1492,0),0))) -> Unit | F17: =IF(ISERROR(OFFSET($D$223,MATCH(A17,$F$224:$F$373,0),0)),"",OFFSET($D$223,MATCH(A17,$F$224:$F$373,0),0)) -> 1 | G17: =IF(ISERROR(OFFSET('HARGA SATUAN'!$I$6,MATCH(C17,'HARGA SATUAN'!$C$7:$C$1492,0),0)),"",OFFSET('HARGA SATUAN'!$I$6,MATCH(C17,'HARGA SATUAN'!$C$7:$C$1492,0),0)) -> 3564900 | H17: =IF(OR(D17="MDU",D17="MDU-KD"),G17*F17,0) -> 3564900 | I17: =IF(D17="HDW",G17*F17,0) -> 0 | J17: =IF(D17="JASA",G17*F17,0) -> 0 | K17: =SUM(H17:J17) -> 3564900
A18: 3 | B18: =IF(C18="","",A18) -> 3 | C18: =IF(ISERROR(OFFSET($C$223,MATCH(A18,$F$224:$F$373,0),0)),"",OFFSET($C$223,MATCH(A18,$F$224:$F$373,0),0)) -> NFA2X-T 3x70+1x70 | D18: =IF(ISERROR(OFFSET('HARGA SATUAN'!$D$6,MATCH(C18,'HARGA SATUAN'!$C$7:$C$1492,0),0)),"",OFFSET('HARGA SATUAN'!$D$6,MATCH(C18,'HARGA SATUAN'!$C$7:$C$1492,0),0)) -> MDU-KD | E18: =IF(B18="+","Unit",IF(ISERROR(OFFSET('HARGA SATUAN'!$E$6,MATCH(C18,'HARGA SATUAN'!$C$7:$C$1492,0),0)),"",OFFSET('HARGA SATUAN'!$E$6,MATCH(C18,'HARGA SATUAN'!$C$7:$C$1492,0),0))) -> Mtr | F18: =IF(ISERROR(OFFSET($D$223,MATCH(A18,$F$224:$F$373,0),0)),"",OFFSET($D$223,MATCH(A18,$F$224:$F$373,0),0)) -> 130 | G18: =IF(ISERROR(OFFSET('HARGA SATUAN'!$I$6,MATCH(C18,'HARGA SATUAN'!$C$7:$C$1492,0),0)),"",OFFSET('HARGA SATUAN'!$I$6,MATCH(C18,'HARGA SATUAN'!$C$7:$C$1492,0),0)) -> 54500 | H18: =IF(OR(D18="MDU",D18="MDU-KD"),G18*F18,0) -> 7085000 | I18: =IF(D18="HDW",G18*F18,0) -> 0 | J18: =IF(D18="JASA",G18*F18,0) -> 0 | K18: =SUM(H18:J18) -> 7085000
A19: 4 | B19: =IF(C19="","",A19) -> 4 | C19: =IF(ISERROR(OFFSET($C$223,MATCH(A19,$F$224:$F$373,0),0)),"",OFFSET($C$223,MATCH(A19,$F$224:$F$373,0),0)) -> NFA2X 4 x 16 mm² | D19: =IF(ISERROR(OFFSET('HARGA SATUAN'!$D$6,MATCH(C19,'HARGA SATUAN'!$C$7:$C$1492,0),0)),"",OFFSET('HARGA SATUAN'!$D$6,MATCH(C19,'HARGA SATUAN'!$C$7:$C$1492,0),0)) -> MDU-KD | E19: =IF(B19="+","Unit",IF(ISERROR(OFFSET('HARGA SATUAN'!$E$6,MATCH(C19,'HARGA SATUAN'!$C$7:$C$1492,0),0)),"",OFFSET('HARGA SATUAN'!$E$6,MATCH(C19,'HARGA SATUAN'!$C$7:$C$1492,0),0))) -> Mtr | F19: =IF(ISERROR(OFFSET($D$223,MATCH(A19,$F$224:$F$373,0),0)),"",OFFSET($D$223,MATCH(A19,$F$224:$F$373,0),0)) -> 50 | G19: =IF(ISERROR(OFFSET('HARGA SATUAN'!$I$6,MATCH(C19,'HARGA SATUAN'!$C$7:$C$1492,0),0)),"",OFFSET('HARGA SATUAN'!$I$6,MATCH(C19,'HARGA SATUAN'!$C$7:$C$1492,0),0)) -> 13500 | H19: =IF(OR(D19="MDU",D19="MDU-KD"),G19*F19,0) -> 675000 | I19: =IF(D19="HDW",G19*F19,0) -> 0 | J19: =IF(D19="JASA",G19*F19,0) -> 0 | K19: =SUM(H19:J19) -> 675000
A20: 5 | B20: =IF(C20="","",A20) | C20: =IF(ISERROR(OFFSET($C$223,MATCH(A20,$F$224:$F$373,0),0)),"",OFFSET($C$223,MATCH(A20,$F$224:$F$373,0),0)) | D20: =IF(ISERROR(OFFSET('HARGA SATUAN'!$D$6,MATCH(C20,'HARGA SATUAN'!$C$7:$C$1492,0),0)),"",OFFSET('HARGA SATUAN'!$D$6,MATCH(C20,'HARGA SATUAN'!$C$7:$C$1492,0),0)) | E20: =IF(B20="+","Unit",IF(ISERROR(OFFSET('HARGA SATUAN'!$E$6,MATCH(C20,'HARGA SATUAN'!$C$7:$C$1492,0),0)),"",OFFSET('HARGA SATUAN'!$E$6,MATCH(C20,'HARGA SATUAN'!$C$7:$C$1492,0),0))) -> 0 | F20: =IF(ISERROR(OFFSET($D$223,MATCH(A20,$F$224:$F$373,0),0)),"",OFFSET($D$223,MATCH(A20,$F$224:$F$373,0),0)) | G20: =IF(ISERROR(OFFSET('HARGA SATUAN'!$I$6,MATCH(C20,'HARGA SATUAN'!$C$7:$C$1492,0),0)),"",OFFSET('HARGA SATUAN'!$I$6,MATCH(C20,'HARGA SATUAN'!$C$7:$C$1492,0),0)) -> 0 | H20: =IF(OR(D20="MDU",D20="MDU-KD"),G20*F20,0) -> 0 | I20: =IF(D20="HDW",G20*F20,0) -> 0 | J20: =IF(D20="JASA",G20*F20,0) -> 0 | K20: =SUM(H20:J20) -> 0
A21: 6 | B21: =IF(C21="","",A21) | C21: =IF(ISERROR(OFFSET($C$223,MATCH(A21,$F$224:$F$373,0),0)),"",OFFSET($C$223,MATCH(A21,$F$224:$F$373,0),0)) | D21: =IF(ISERROR(OFFSET('HARGA SATUAN'!$D$6,MATCH(C21,'HARGA SATUAN'!$C$7:$C$1492,0),0)),"",OFFSET('HARGA SATUAN'!$D$6,MATCH(C21,'HARGA SATUAN'!$C$7:$C$1492,0),0)) | E21: =IF(B21="+","Unit",IF(ISERROR(OFFSET('HARGA SATUAN'!$E$6,MATCH(C21,'HARGA SATUAN'!$C$7:$C$1492,0),0)),"",OFFSET('HARGA SATUAN'!$E$6,MATCH(C21,'HARGA SATUAN'!$C$7:$C$1492,0),0))) -> 0 | F21: =IF(ISERROR(OFFSET($D$223,MATCH(A21,$F$224:$F$373,0),0)),"",OFFSET($D$223,MATCH(A21,$F$224:$F$373,0),0)) | G21: =IF(ISERROR(OFFSET('HARGA SATUAN'!$I$6,MATCH(C21,'HARGA SATUAN'!$C$7:$C$1492,0),0)),"",OFFSET('HARGA SATUAN'!$I$6,MATCH(C21,'HARGA SATUAN'!$C$7:$C$1492,0),0)) -> 0 | H21: =IF(OR(D21="MDU",D21="MDU-KD"),G21*F21,0) -> 0 | I21: =IF(D21="HDW",G21*F21,0) -> 0 | J21: =IF(D21="JASA",G21*F21,0) -> 0 | K21: =SUM(H21:J21) -> 0
A22: 7 | B22: =IF(C22="","",A22) | C22: =IF(ISERROR(OFFSET($C$223,MATCH(A22,$F$224:$F$373,0),0)),"",OFFSET($C$223,MATCH(A22,$F$224:$F$373,0),0)) | D22: =IF(ISERROR(OFFSET('HARGA SATUAN'!$D$6,MATCH(C22,'HARGA SATUAN'!$C$7:$C$1492,0),0)),"",OFFSET('HARGA SATUAN'!$D$6,MATCH(C22,'HARGA SATUAN'!$C$7:$C$1492,0),0)) | E22: =IF(B22="+","Unit",IF(ISERROR(OFFSET('HARGA SATUAN'!$E$6,MATCH(C22,'HARGA SATUAN'!$C$7:$C$1492,0),0)),"",OFFSET('HARGA SATUAN'!$E$6,MATCH(C22,'HARGA SATUAN'!$C$7:$C$1492,0),0))) -> 0 | F22: =IF(ISERROR(OFFSET($D$223,MATCH(A22,$F$224:$F$373,0),0)),"",OFFSET($D$223,MATCH(A22,$F$224:$F$373,0),0)) | G22: =IF(ISERROR(OFFSET('HARGA SATUAN'!$I$6,MATCH(C22,'HARGA SATUAN'!$C$7:$C$1492,0),0)),"",OFFSET('HARGA SATUAN'!$I$6,MATCH(C22,'HARGA SATUAN'!$C$7:$C$1492,0),0)) -> 0 | H22: =IF(OR(D22="MDU",D22="MDU-KD"),G22*F22,0) -> 0 | I22: =IF(D22="HDW",G22*F22,0) -> 0 | J22: =IF(D22="JASA",G22*F22,0) -> 0 | K22: =SUM(H22:J22) -> 0
A23: 8 | B23: =IF(C23="","",A23) | C23: =IF(ISERROR(OFFSET($C$223,MATCH(A23,$F$224:$F$373,0),0)),"",OFFSET($C$223,MATCH(A23,$F$224:$F$373,0),0)) | D23: =IF(ISERROR(OFFSET('HARGA SATUAN'!$D$6,MATCH(C23,'HARGA SATUAN'!$C$7:$C$1492,0),0)),"",OFFSET('HARGA SATUAN'!$D$6,MATCH(C23,'HARGA SATUAN'!$C$7:$C$1492,0),0)) | E23: =IF(B23="+","Unit",IF(ISERROR(OFFSET('HARGA SATUAN'!$E$6,MATCH(C23,'HARGA SATUAN'!$C$7:$C$1492,0),0)),"",OFFSET('HARGA SATUAN'!$E$6,MATCH(C23,'HARGA SATUAN'!$C$7:$C$1492,0),0))) -> 0 | F23: =IF(ISERROR(OFFSET($D$223,MATCH(A23,$F$224:$F$373,0),0)),"",OFFSET($D$223,MATCH(A23,$F$224:$F$373,0),0)) | G23: =IF(ISERROR(OFFSET('HARGA SATUAN'!$I$6,MATCH(C23,'HARGA SATUAN'!$C$7:$C$1492,0),0)),"",OFFSET('HARGA SATUAN'!$I$6,MATCH(C23,'HARGA SATUAN'!$C$7:$C$1492,0),0)) -> 0 | H23: =IF(OR(D23="MDU",D23="MDU-KD"),G23*F23,0) -> 0 | I23: =IF(D23="HDW",G23*F23,0) -> 0 | J23: =IF(D23="JASA",G23*F23,0) -> 0 | K23: =SUM(H23:J23) -> 0
A24: 9 | B24: =IF(C24="","",A24) | C24: =IF(ISERROR(OFFSET($C$223,MATCH(A24,$F$224:$F$373,0),0)),"",OFFSET($C$223,MATCH(A24,$F$224:$F$373,0),0)) | D24: =IF(ISERROR(OFFSET('HARGA SATUAN'!$D$6,MATCH(C24,'HARGA SATUAN'!$C$7:$C$1492,0),0)),"",OFFSET('HARGA SATUAN'!$D$6,MATCH(C24,'HARGA SATUAN'!$C$7:$C$1492,0),0)) | E24: =IF(B24="+","Unit",IF(ISERROR(OFFSET('HARGA SATUAN'!$E$6,MATCH(C24,'HARGA SATUAN'!$C$7:$C$1492,0),0)),"",OFFSET('HARGA SATUAN'!$E$6,MATCH(C24,'HARGA SATUAN'!$C$7:$C$1492,0),0))) -> 0 | F24: =IF(ISERROR(OFFSET($D$223,MATCH(A24,$F$224:$F$373,0),0)),"",OFFSET($D$223,MATCH(A24,$F$224:$F$373,0),0)) | G24: =IF(ISERROR(OFFSET('HARGA SATUAN'!$I$6,MATCH(C24,'HARGA SATUAN'!$C$7:$C$1492,0),0)),"",OFFSET('HARGA SATUAN'!$I$6,MATCH(C24,'HARGA SATUAN'!$C$7:$C$1492,0),0)) -> 0 | H24: =IF(OR(D24="MDU",D24="MDU-KD"),G24*F24,0) -> 0 | I24: =IF(D24="HDW",G24*F24,0) -> 0 | J24: =IF(D24="JASA",G24*F24,0) -> 0 | K24: =SUM(H24:J24) -> 0
A25: 10 | B25: =IF(C25="","",A25) | C25: =IF(ISERROR(OFFSET($C$223,MATCH(A25,$F$224:$F$373,0),0)),"",OFFSET($C$223,MATCH(A25,$F$224:$F$373,0),0)) | D25: =IF(ISERROR(OFFSET('HARGA SATUAN'!$D$6,MATCH(C25,'HARGA SATUAN'!$C$7:$C$1492,0),0)),"",OFFSET('HARGA SATUAN'!$D$6,MATCH(C25,'HARGA SATUAN'!$C$7:$C$1492,0),0)) | E25: =IF(B25="+","Unit",IF(ISERROR(OFFSET('HARGA SATUAN'!$E$6,MATCH(C25,'HARGA SATUAN'!$C$7:$C$1492,0),0)),"",OFFSET('HARGA SATUAN'!$E$6,MATCH(C25,'HARGA SATUAN'!$C$7:$C$1492,0),0))) -> 0 | F25: =IF(ISERROR(OFFSET($D$223,MATCH(A25,$F$224:$F$373,0),0)),"",OFFSET($D$223,MATCH(A25,$F$224:$F$373,0),0)) | G25: =IF(ISERROR(OFFSET('HARGA SATUAN'!$I$6,MATCH(C25,'HARGA SATUAN'!$C$7:$C$1492,0),0)),"",OFFSET('HARGA SATUAN'!$I$6,MATCH(C25,'HARGA SATUAN'!$C$7:$C$1492,0),0)) -> 0 | H25: =IF(OR(D25="MDU",D25="MDU-KD"),G25*F25,0) -> 0 | I25: =IF(D25="HDW",G25*F25,0) -> 0 | J25: =IF(D25="JASA",G25*F25,0) -> 0 | K25: =SUM(H25:J25) -> 0
A26: 11 | B26: =IF(C26="","",A26) | C26: =IF(ISERROR(OFFSET($C$223,MATCH(A26,$F$224:$F$373,0),0)),"",OFFSET($C$223,MATCH(A26,$F$224:$F$373,0),0)) | D26: =IF(ISERROR(OFFSET('HARGA SATUAN'!$D$6,MATCH(C26,'HARGA SATUAN'!$C$7:$C$1492,0),0)),"",OFFSET('HARGA SATUAN'!$D$6,MATCH(C26,'HARGA SATUAN'!$C$7:$C$1492,0),0)) | E26: =IF(B26="+","Unit",IF(ISERROR(OFFSET('HARGA SATUAN'!$E$6,MATCH(C26,'HARGA SATUAN'!$C$7:$C$1492,0),0)),"",OFFSET('HARGA SATUAN'!$E$6,MATCH(C26,'HARGA SATUAN'!$C$7:$C$1492,0),0))) -> 0 | F26: =IF(ISERROR(OFFSET($D$223,MATCH(A26,$F$224:$F$373,0),0)),"",OFFSET($D$223,MATCH(A26,$F$224:$F$373,0),0)) | G26: =IF(ISERROR(OFFSET('HARGA SATUAN'!$I$6,MATCH(C26,'HARGA SATUAN'!$C$7:$C$1492,0),0)),"",OFFSET('HARGA SATUAN'!$I$6,MATCH(C26,'HARGA SATUAN'!$C$7:$C$1492,0),0)) -> 0 | H26: =IF(OR(D26="MDU",D26="MDU-KD"),G26*F26,0) -> 0 | I26: =IF(D26="HDW",G26*F26,0) -> 0 | J26: =IF(D26="JASA",G26*F26,0) -> 0 | K26: =SUM(H26:J26) -> 0
A27: 12 | B27: =IF(C27="","",A27) | C27: =IF(ISERROR(OFFSET($C$223,MATCH(A27,$F$224:$F$373,0),0)),"",OFFSET($C$223,MATCH(A27,$F$224:$F$373,0),0)) | D27: =IF(ISERROR(OFFSET('HARGA SATUAN'!$D$6,MATCH(C27,'HARGA SATUAN'!$C$7:$C$1492,0),0)),"",OFFSET('HARGA SATUAN'!$D$6,MATCH(C27,'HARGA SATUAN'!$C$7:$C$1492,0),0)) | E27: =IF(B27="+","Unit",IF(ISERROR(OFFSET('HARGA SATUAN'!$E$6,MATCH(C27,'HARGA SATUAN'!$C$7:$C$1492,0),0)),"",OFFSET('HARGA SATUAN'!$E$6,MATCH(C27,'HARGA SATUAN'!$C$7:$C$1492,0),0))) -> 0 | F27: =IF(ISERROR(OFFSET($D$223,MATCH(A27,$F$224:$F$373,0),0)),"",OFFSET($D$223,MATCH(A27,$F$224:$F$373,0),0)) | G27: =IF(ISERROR(OFFSET('HARGA SATUAN'!$I$6,MATCH(C27,'HARGA SATUAN'!$C$7:$C$1492,0),0)),"",OFFSET('HARGA SATUAN'!$I$6,MATCH(C27,'HARGA SATUAN'!$C$7:$C$1492,0),0)) -> 0 | H27: =IF(OR(D27="MDU",D27="MDU-KD"),G27*F27,0) -> 0 | I27: =IF(D27="HDW",G27*F27,0) -> 0 | J27: =IF(D27="JASA",G27*F27,0) -> 0 | K27: =SUM(H27:J27) -> 0
... A165: 150 | B165: =IF(C165="","",A165) | C165: =IF(ISERROR(OFFSET($C$223,MATCH(A165,$F$224:$F$373,0),0)),"",OFFSET($C$223,MATCH(A165,$F$224:$F$373,0),0)) | D165: =IF(ISERROR(OFFSET('HARGA SATUAN'!$D$6,MATCH(C165,'HARGA SATUAN'!$C$7:$C$1492,0),0)),"",OFFSET('HARGA SATUAN'!$D$6,MATCH(C165,'HARGA SATUAN'!$C$7:$C$1492,0),0)) | E165: =IF(B165="+","Unit",IF(ISERROR(OFFSET('HARGA SATUAN'!$E$6,MATCH(C165,'HARGA SATUAN'!$C$7:$C$1492,0),0)),"",OFFSET('HARGA SATUAN'!$E$6,MATCH(C165,'HARGA SATUAN'!$C$7:$C$1492,0),0))) -> 0 | F165: =IF(ISERROR(OFFSET($D$223,MATCH(A165,$F$224:$F$373,0),0)),"",OFFSET($D$223,MATCH(A165,$F$224:$F$373,0),0)) | G165: =IF(ISERROR(OFFSET('HARGA SATUAN'!$I$6,MATCH(C165,'HARGA SATUAN'!$C$7:$C$1492,0),0)),"",OFFSET('HARGA SATUAN'!$I$6,MATCH(C165,'HARGA SATUAN'!$C$7:$C$1492,0),0)) -> 0 | H165: =IF(OR(D165="MDU",D165="MDU-KD"),G165*F165,0) -> 0 | I165: =IF(D165="HDW",G165*F165,0) -> 0 | J165: =IF(D165="JASA",G165*F165,0) -> 0 | K165: =SUM(H165:J165) -> 0
C168: Jumlah MDU - Hardware - Jasa | G168: : | H168: =SUM(H14:H167) -> 12752300 | I168: =SUM(I14:I167) -> 0 | J168: =SUM(J14:J167) -> 0 | K168: =SUM(K14:K167) -> 12752300
C169: PPN 10% | G169: : | H169: =H168*0.1 -> 1275230 | I169: =I168*0.1 -> 0 | J169: =J168*0.1 -> 0 | K169: =K168*0.1 -> 1275230
C170: Jumlah Total | G170: : | H170: =SUM(H168:H169) -> 14027530 | I170: =SUM(I168:I169) -> 0 | J170: =SUM(J168:J169) -> 0 | K170: =SUM(K168:K169) -> 14027530
B171: ="Terbilang : ( "&L172&" Rupiah )" -> #NAME?
L172: =PROPER([91]!terbilang(K170)) -> #NAME?
B173: ="Harga yang dipakai adalah "&'HARGA SATUAN'!I5&"" -> Harga yang dipakai adalah RAB HSS 2023
B223: NO | C223: JENIS MDU
B224: 1 | C224: =IF(ISERROR(OFFSET('HARGA SATUAN'!$C$6,MATCH('REKAP MDU'!B224,'HARGA SATUAN'!$L$7:$L$1455,0),0)),"",OFFSET('HARGA SATUAN'!$C$6,MATCH('REKAP MDU'!B224,'HARGA SATUAN'!$L$7:$L$1455,0),0)) -> KWH MPB; 1P;230V;5(60)A;1;2W | D224: =SUMIFS(RAB!$F$14:$F$80,RAB!$C$14:$C$80,C224) -> 0 | E224: =IF(D224=0,0,1) -> 0 | F224: =IF(D224=0,0,SUM($E$223:E224)) -> 0
B225: 2 | C225: =IF(ISERROR(OFFSET('HARGA SATUAN'!$C$6,MATCH('REKAP MDU'!B225,'HARGA SATUAN'!$L$7:$L$1455,0),0)),"",OFFSET('HARGA SATUAN'!$C$6,MATCH('REKAP MDU'!B225,'HARGA SATUAN'!$L$7:$L$1455,0),0)) -> KWH Elektronik; 1P; 2W; 230 V; 5(40) A; kls 1 (combo); register drum | D225: =SUMIFS(RAB!$F$14:$F$80,RAB!$C$14:$C$80,C225) -> 0 | E225: =IF(D225=0,0,1) -> 0 | F225: =IF(D225=0,0,SUM($E$223:E225)) -> 0
B226: 3 | C226: =IF(ISERROR(OFFSET('HARGA SATUAN'!$C$6,MATCH('REKAP MDU'!B226,'HARGA SATUAN'!$L$7:$L$1455,0),0)),"",OFFSET('HARGA SATUAN'!$C$6,MATCH('REKAP MDU'!B226,'HARGA SATUAN'!$L$7:$L$1455,0),0)) -> KWH Elektronik; 1P; 2W; 230 V; 5(100) A; kls 1 termasuk modem 3G/4G | D226: =SUMIFS(RAB!$F$14:$F$80,RAB!$C$14:$C$80,C226) -> 0 | E226: =IF(D226=0,0,1) -> 0 | F226: =IF(D226=0,0,SUM($E$223:E226)) -> 0
B227: 4 | C227: =IF(ISERROR(OFFSET('HARGA SATUAN'!$C$6,MATCH('REKAP MDU'!B227,'HARGA SATUAN'!$L$7:$L$1455,0),0)),"",OFFSET('HARGA SATUAN'!$C$6,MATCH('REKAP MDU'!B227,'HARGA SATUAN'!$L$7:$L$1455,0),0)) -> KWH Elektronik; 3P; 4W; 57.7-100V/220-400V; 5 A; kls 0.2 (meter pembanding) | D227: =SUMIFS(RAB!$F$14:$F$80,RAB!$C$14:$C$80,C227) -> 0 | E227: =IF(D227=0,0,1) -> 0 | F227: =IF(D227=0,0,SUM($E$223:E227)) -> 0
B228: 5 | C228: =IF(ISERROR(OFFSET('HARGA SATUAN'!$C$6,MATCH('REKAP MDU'!B228,'HARGA SATUAN'!$L$7:$L$1455,0),0)),"",OFFSET('HARGA SATUAN'!$C$6,MATCH('REKAP MDU'!B228,'HARGA SATUAN'!$L$7:$L$1455,0),0)) -> KWH Elektronik; 3P; 4W; 220/380V; 5(80) A; kls 1 (Pengukuran Langsung) | D228: =SUMIFS(RAB!$F$14:$F$80,RAB!$C$14:$C$80,C228) -> 1 | E228: =IF(D228=0,0,1) -> 1 | F228: =IF(D228=0,0,SUM($E$223:E228)) -> 1
B229: 6 | C229: =IF(ISERROR(OFFSET('HARGA SATUAN'!$C$6,MATCH('REKAP MDU'!B229,'HARGA SATUAN'!$L$7:$L$1455,0),0)),"",OFFSET('HARGA SATUAN'!$C$6,MATCH('REKAP MDU'!B229,'HARGA SATUAN'!$L$7:$L$1455,0),0)) -> KWH Elektronik; 3P; 4W; 57.7-100V/220-400V; 5(10) A; kls 0.5 (Pengukuran Tidak Langsung) | D229: =SUMIFS(RAB!$F$14:$F$80,RAB!$C$14:$C$80,C229) -> 0 | E229: =IF(D229=0,0,1) -> 0 | F229: =IF(D229=0,0,SUM($E$223:E229)) -> 0
B230: 7 | C230: =IF(ISERROR(OFFSET('HARGA SATUAN'!$C$6,MATCH('REKAP MDU'!B230,'HARGA SATUAN'!$L$7:$L$1455,0),0)),"",OFFSET('HARGA SATUAN'!$C$6,MATCH('REKAP MDU'!B230,'HARGA SATUAN'!$L$7:$L$1455,0),0)) -> KWH Elektronik; 3P; 4W; 220/380V; 5(10); kls 1 (Pengukuran Tidak Langsung) | D230: =SUMIFS(RAB!$F$14:$F$80,RAB!$C$14:$C$80,C230) -> 0 | E230: =IF(D230=0,0,1) -> 0 | F230: =IF(D230=0,0,SUM($E$223:E230)) -> 0
B231: 8 | C231: =IF(ISERROR(OFFSET('HARGA SATUAN'!$C$6,MATCH('REKAP MDU'!B231,'HARGA SATUAN'!$L$7:$L$1455,0),0)),"",OFFSET('HARGA SATUAN'!$C$6,MATCH('REKAP MDU'!B231,'HARGA SATUAN'!$L$7:$L$1455,0),0)) -> MCB 1 Fasa 2 A | D231: =SUMIFS(RAB!$F$14:$F$80,RAB!$C$14:$C$80,C231) -> 0 | E231: =IF(D231=0,0,1) -> 0 | F231: =IF(D231=0,0,SUM($E$223:E231)) -> 0
...

Sheet Sheet1
D4: 3
D5: 1

Sheet HARGA SATUAN
B2: HARGA SATUAN
B4: NO. | C4: MATERIAL + SIZE | D4: GOL | E4: SAT | F4: RAB SKK 2022 | G4: RAB HSS 2023 | H4: KETERANGAN | I4: HARGA YANG DIPAKAI DI RAB
I5: RAB HSS 2023
K6: =MAX(L7:L1455) -> 137 | M6: =MAX(M7:M1455) -> 2.012275e+08
F7: =(IF(D7="JASA",G7*#REF!,0))+(IF(D7="HDW",G7*#REF!,0))+(IF(D7="MDU",G7*#REF!,0))+(IF(D7="MDU-KD",G7*#REF!,0)) -> 0 | G7: 0 | I7: =IF($I$5=$G$4,G7,(IF($I$5=$F$4,(IF(F7=0,G7,F7)),0))) -> 0 | J7: =IF(D7="MDU-KD",1,0) -> 0 | K7: =IF(D7="HDW",1,0) -> 0 | L7: =IF(J7=1,SUM($J$6:J7),0) -> 0 | M7: =IF(K7=1,SUM($K$6:K7),0) -> 0 | N7: =IF(L7=0,M7,L7) -> 0 | O7: =IF(E7=0,0,IF(LEFT(C7,11)="Tiang Beton",1,0)) -> 0 | P7: =IF(O7=1,SUM($O$6:O7),0) -> 0
B8: A | C8: ALAT PENGUKUR DAN PEMBATAS | F8: =(IF(D8="JASA",G8*'[92]DETAIL USULAN'!$K$58,0))+(IF(D8="HDW",G8*'[92]DETAIL USULAN'!$J$58,0))+(IF(D8="MDU",G8*'[92]DETAIL USULAN'!$I$58,0))+(IF(D8="MDU-KD",G8*'[92]DETAIL USULAN'!$I$58,0)) -> 0 | G8: 0 | I8: =IF($I$5=$G$4,G8,(IF($I$5=$F$4,(IF(F8=0,G8,F8)),0))) -> 0 | J8: =IF(D8="MDU-KD",1,0) -> 0 | K8: =IF(D8="HDW",1,0) -> 0 | L8: =IF(J8=1,SUM($J$6:J8),0) -> 0 | M8: =IF(K8=1,SUM($K$6:K8),0) -> 0 | N8: =IF(L8=0,M8,L8) -> 0 | O8: =IF(E8=0,0,IF(LEFT(C8,11)="Tiang Beton",1,0)) -> 0 | P8: =IF(O8=1,SUM($O$6:O8),0) -> 0
B9: 1 | C9: KWH MPB; 1P;230V;5(60)A;1;2W | D9: MDU-KD | E9: Bh | F9: 294100 | G9: 327600 | I9: =IF($I$5=$G$4,G9,(IF($I$5=$F$4,F9,0))) -> 327600 | J9: =IF(D9="MDU-KD",1,0) -> 1 | K9: =IF(D9="HDW",1,0) -> 0 | L9: =IF(J9=1,SUM($J$6:J9),0) -> 1 | M9: =IF(K9=1,SUM($K$6:K9),0) -> 0 | N9: =IF(L9=0,M9,L9) -> 1 | O9: =IF(E9=0,0,IF(LEFT(C9,11)="Tiang Beton",1,0)) -> 0 | P9: =IF(O9=1,SUM($O$6:O9),0) -> 0
B10: 2 | C10: KWH MPB; 3P; 4W; 230/400 V; 5(80) A; Class 1 | D10: HDW | E10: Bh | F10: 1719200 | G10: 1719200 | I10: =IF($I$5=$G$4,G10,(IF($I$5=$F$4,F10,0))) -> 1719200 | J10: =IF(D10="MDU-KD",1,0) -> 0 | K10: =IF(D10="HDW",1,0) -> 1 | L10: =IF(J10=1,SUM($J$6:J10),0) -> 0 | M10: =IF(K10=1,SUM($K$6:K10),0) -> 138 | N10: =IF(L10=0,M10,L10) -> 138 | O10: =IF(E10=0,0,IF(LEFT(C10,11)="Tiang Beton",1,0)) -> 0 | P10: =IF(O10=1,SUM($O$6:O10),0) -> 0
B11: 3 | C11: KWH Elektronik; 1P; 2W; 230 V; 5(40) A; kls 1 (combo); register drum | D11: MDU-KD | E11: Bh | F11: 151000 | G11: 168200 | I11: =IF($I$5=$G$4,G11,(IF($I$5=$F$4,F11,0))) -> 168200 | J11: =IF(D11="MDU-KD",1,0) -> 1 | K11: =IF(D11="HDW",1,0) -> 0 | L11: =IF(J11=1,SUM($J$6:J11),0) -> 2 | M11: =IF(K11=1,SUM($K$6:K11),0) -> 0 | N11: =IF(L11=0,M11,L11) -> 2 | O11: =IF(E11=0,0,IF(LEFT(C11,11)="Tiang Beton",1,0)) -> 0 | P11: =IF(O11=1,SUM($O$6:O11),0) -> 0
B12: 4 | C12: KWH Elektronik; 1P; 2W; 230 V; 5(100) A; kls 1 termasuk modem 3G/4G | D12: MDU-KD | E12: Bh | F12: 1430000 | G12: 1740750 | I12: =IF($I$5=$G$4,G12,(IF($I$5=$F$4,F12,0))) -> 1740750 | J12: =IF(D12="MDU-KD",1,0) -> 1 | K12: =IF(D12="HDW",1,0) -> 0 | L12: =IF(J12=1,SUM($J$6:J12),0) -> 3 | M12: =IF(K12=1,SUM($K$6:K12),0) -> 0 | N12: =IF(L12=0,M12,L12) -> 3 | O12: =IF(E12=0,0,IF(LEFT(C12,11)="Tiang Beton",1,0)) -> 0 | P12: =IF(O12=1,SUM($O$6:O12),0) -> 0
B13: 5 | C13: KWH Elektronik; 3P; 4W; 57.7-100V/220-400V; 5 A; kls 0.2 (meter pembanding) | D13: MDU-KD | E13: Bh | F13: 16495000 | G13: 18373800 | I13: =IF($I$5=$G$4,G13,(IF($I$5=$F$4,F13,0))) -> 18373800 | J13: =IF(D13="MDU-KD",1,0) -> 1 | K13: =IF(D13="HDW",1,0) -> 0 | L13: =IF(J13=1,SUM($J$6:J13),0) -> 4 | M13: =IF(K13=1,SUM($K$6:K13),0) -> 0 | N13: =IF(L13=0,M13,L13) -> 4 | O13: =IF(E13=0,0,IF(LEFT(C13,11)="Tiang Beton",1,0)) -> 0 | P13: =IF(O13=1,SUM($O$6:O13),0) -> 0
B14: 6 | C14: KWH Elektronik; 3P; 4W; 220/380V; 5(80) A; kls 1 (Pengukuran Langsung) | D14: MDU-KD | E14: Bh | F14: 1281430 | G14: 1427400 | I14: =IF($I$5=$G$4,G14,(IF($I$5=$F$4,F14,0))) -> 1427400 | J14: =IF(D14="MDU-KD",1,0) -> 1 | K14: =IF(D14="HDW",1,0) -> 0 | L14: =IF(J14=1,SUM($J$6:J14),0) -> 5 | M14: =IF(K14=1,SUM($K$6:K14),0) -> 0 | N14: =IF(L14=0,M14,L14) -> 5 | O14: =IF(E14=0,0,IF(LEFT(C14,11)="Tiang Beton",1,0)) -> 0 | P14: =IF(O14=1,SUM($O$6:O14),0) -> 0
B15: 7 | C15: KWH Elektronik; 3P; 4W; 57.7-100V/220-400V; 5(10) A; kls 0.5 (Pengukuran Tidak Langsung) | D15: MDU-KD | E15: Bh | F15: 1344430 | G15: 1497600 | I15: =IF($I$5=$G$4,G15,(IF($I$5=$F$4,F15,0))) -> 1497600 | J15: =IF(D15="MDU-KD",1,0) -> 1 | K15: =IF(D15="HDW",1,0) -> 0 | L15: =IF(J15=1,SUM($J$6:J15),0) -> 6 | M15: =IF(K15=1,SUM($K$6:K15),0) -> 0 | N15: =IF(L15=0,M15,L15) -> 6 | O15: =IF(E15=0,0,IF(LEFT(C15,11)="Tiang Beton",1,0)) -> 0 | P15: =IF(O15=1,SUM($O$6:O15),0) -> 0
B16: 8 | C16: KWH Elektronik; 3P; 4W; 220/380V; 5(10); kls 1 (Pengukuran Tidak Langsung) | D16: MDU-KD | E16: Bh | F16: 1350430 | G16: 1504200 | I16: =IF($I$5=$G$4,G16,(IF($I$5=$F$4,F16,0))) -> 1504200 | J16: =IF(D16="MDU-KD",1,0) -> 1 | K16: =IF(D16="HDW",1,0) -> 0 | L16: =IF(J16=1,SUM($J$6:J16),0) -> 7 | M16: =IF(K16=1,SUM($K$6:K16),0) -> 0 | N16: =IF(L16=0,M16,L16) -> 7 | O16: =IF(E16=0,0,IF(LEFT(C16,11)="Tiang Beton",1,0)) -> 0 | P16: =IF(O16=1,SUM($O$6:O16),0) -> 0
B17: 9 | C17: Modem 3G/4G | D17: HDW | E17: Unit | F17: 1000000 | G17: 1113900 | I17: =IF($I$5=$G$4,G17,(IF($I$5=$F$4,F17,0))) -> 1113900 | J17: =IF(D17="MDU-KD",1,0) -> 0 | K17: =IF(D17="HDW",1,0) -> 1 | L17: =IF(J17=1,SUM($J$6:J17),0) -> 0 | M17: =IF(K17=1,SUM($K$6:K17),0) -> 139 | N17: =IF(L17=0,M17,L17) -> 139 | O17: =IF(E17=0,0,IF(LEFT(C17,11)="Tiang Beton",1,0)) -> 0 | P17: =IF(O17=1,SUM($O$6:O17),0) -> 0
B18: 10 | C18: MCB 1 Fasa 2 A | D18: MDU-KD | E18: Bh | F18: 35000 | G18: 39000 | I18: =IF($I$5=$G$4,G18,(IF($I$5=$F$4,F18,0))) -> 39000 | J18: =IF(D18="MDU-KD",1,0) -> 1 | K18: =IF(D18="HDW",1,0) -> 0 | L18: =IF(J18=1,SUM($J$6:J18),0) -> 8 | M18: =IF(K18=1,SUM($K$6:K18),0) -> 0 | N18: =IF(L18=0,M18,L18) -> 8 | O18: =IF(E18=0,0,IF(LEFT(C18,11)="Tiang Beton",1,0)) -> 0 | P18: =IF(O18=1,SUM($O$6:O18),0) -> 0
